Workbook
Name Country_list: Lookups!$H$3:$H$252
Name Currency_list: Lookups!$P$3:$P$163
Name current_date: Parameters!$D$9
Name Development_classes: Parameters!$C$14:$C$213
Name IQ_CH: 110000
Name IQ_CQ: 5000
Name IQ_CY: 10000
Name IQ_DAILY: 500000
Name IQ_FH: 100000
Name IQ_FQ: 500
Name IQ_FY: 1000
Name IQ_LTM: 2000
Name IQ_MONTH: 15000
Name IQ_NTM: 6000
Name IQ_WEEK: 50000
Name IQ_YTD: 3000
Name LDF_type_options: Lookups!$R$3:$R$6
Name LOBs_names: Lookups!$B$3:$B$25
Name month_final_development: Parameters!$D$8
Name month_first_development: Parameters!$D$5
Name P_NP_types: Lookups!$E$3:$E$6
Name Projection_classes: Parameters!$C$219:$C$418
Name re_insurance_list: Lookups!$N$3:$N$5
Name Region_list: Lookups!$K$3:$K$8
Name triangle_grouping_data: Parameters!$C$219:$AA$418
Name triangle_increments_months: Parameters!$D$6
Name triangle_start_date: Parameters!$D$4

Sheet Parameters
B3: Triangle Shape Parameters | E3: guide | F3: Checks
C4: Triangle start (t=0) date | D4: 36892 | E4: YYYY-MM-DD | F4: =triangle_start_date=Triangles!F3 -> TRUE | H4: Mandatory
C5: Month of first development | D5: 6 | E5: first month in triangle | H5: Optional
C6: Development period increments (months) | D6: 12 | E6: triangle increments (column)
C7: Origin period increments (months) | D7: 12 | E7: triangle increments (row)
C8: Month of final development | D8: 294 | E8: Latest month in the largest triangle | F8: =IF(ISERROR(MATCH(month_final_development,Triangles!$G$2:$FA$2, 0)), "Can't find this development month in triangle. Please be consistent with Triangle.", "OK") -> OK
C9: Inception Date | D9: 46023 | E9: YYYY-MM-DD
C10: Expiry Date | D10: 46387 | E10: YYYY-MM-DD
B11: Triangular data list (LOB/Class)
Q12: Cedant Business Segment Names (Optional)
B13: # | C13: Triangle Name | D13: Proportional/Non-proportional | E13: Start Year | F13: End Year | G13: Region | H13: Country | I13: Re/Ins/Retro | J13: LT LOB 1 (Dropdown List) | K13: LT LOB 1 Allocation | L13: LT LOB 2 (Dropdown List) | M13: LT LOB 2 Allocation | N13: LT LOB 3 (Dropdown List) | O13: LT LOB 3 Allocation | P13: LT LOB 4 (Dropdown List) | Q13: LT LOB 4 Allocation | R13: LT LOB 5 (Dropdown List) | S13: LT LOB 5 Allocation | T13: Allocation Check | U13: Currency | V13: Currency Rate | W13: Segment 1 | X13: Segment 2 | Y13: Segment 3 | Z13: Segment 4 | AA13: Segment 5 | AB13: Premium Triangle Source | AC13: Incurred Triangle Source | AD13: Paid Triangle Source | AE13: Ultimate Triangle Source
B14: 1 | C14: Umbrella Ex C V Starr | D14: Proportional | E14: 2001 | F14: 2025 | G14: North America | J14: Casualty | K14: 1 | T14: =IF(AND(C14<>"",SUM(K14,M14,O14,Q14,S14)=1),"pass",IF(AND(C14="",SUM(K14,M14,O14,Q14,S14)=0),"pass","fail")) -> pass | AB14: Cedant provided | AC14: Cedant provided | AD14: Cedant provided
B15: 2 | C15: General Liability ex ARL | D15: Proportional | E15: 2001 | F15: 2025 | G15: North America | J15: Casualty | K15: 1 | T15: =IF(AND(C15<>"",SUM(K15,M15,O15,Q15,S15)=1),"pass",IF(AND(C15="",SUM(K15,M15,O15,Q15,S15)=0),"pass","fail")) -> pass | AB15: Cedant provided | AC15: Cedant provided | AD15: Cedant provided
B16: 3 | C16: Risk Management | D16: Proportional | E16: 2001 | F16: 2025 | G16: North America | J16: Casualty | K16: 1 | T16: =IF(AND(C16<>"",SUM(K16,M16,O16,Q16,S16)=1),"pass",IF(AND(C16="",SUM(K16,M16,O16,Q16,S16)=0),"pass","fail")) -> pass | AB16: Cedant provided | AC16: Cedant provided | AD16: Cedant provided
B17: 4 | C17: Auto Liability | D17: Proportional | E17: 2001 | F17: 2025 | G17: North America | J17: Casualty | K17: 1 | T17: =IF(AND(C17<>"",SUM(K17,M17,O17,Q17,S17)=1),"pass",IF(AND(C17="",SUM(K17,M17,O17,Q17,S17)=0),"pass","fail")) -> pass | AB17: Cedant provided | AC17: Cedant provided | AD17: Cedant provided
B18: 5 | C18: EverSports | D18: Proportional | E18: 2001 | F18: 2025 | G18: North America | J18: Casualty | K18: 1 | T18: =IF(AND(C18<>"",SUM(K18,M18,O18,Q18,S18)=1),"pass",IF(AND(C18="",SUM(K18,M18,O18,Q18,S18)=0),"pass","fail")) -> pass | AB18: Cedant provided | AC18: Cedant provided | AD18: Cedant provided
B19: 6 | C19: California Workers Compensation | D19: Proportional | E19: 2001 | F19: 2025 | G19: North America | J19: Casualty | K19: 1 | T19: =IF(AND(C19<>"",SUM(K19,M19,O19,Q19,S19)=1),"pass",IF(AND(C19="",SUM(K19,M19,O19,Q19,S19)=0),"pass","fail")) -> pass | AB19: Cedant provided | AC19: Cedant provided | AD19: Cedant provided
B20: 7 | C20: Management Liability Excess | D20: Non Proportional | E20: 2001 | F20: 2025 | G20: North America | J20: Casualty | K20: 1 | T20: =IF(AND(C20<>"",SUM(K20,M20,O20,Q20,S20)=1),"pass",IF(AND(C20="",SUM(K20,M20,O20,Q20,S20)=0),"pass","fail")) -> pass
B21: 8 | C21: Management Liability Primary | D21: Proportional | E21: 2001 | F21: 2025 | G21: North America | J21: Casualty | K21: 1 | T21: =IF(AND(C21<>"",SUM(K21,M21,O21,Q21,S21)=1),"pass",IF(AND(C21="",SUM(K21,M21,O21,Q21,S21)=0),"pass","fail")) -> pass
B22: 9 | C22: Canada Casualty | D22: Proportional | E22: 2001 | F22: 2025 | G22: North America | J22: Casualty | K22: 1 | T22: =IF(AND(C22<>"",SUM(K22,M22,O22,Q22,S22)=1),"pass",IF(AND(C22="",SUM(K22,M22,O22,Q22,S22)=0),"pass","fail")) -> pass
B23: 10 | C23: Countrywide Workers Compensation | D23: Proportional | E23: 2001 | F23: 2025 | G23: North America | J23: Casualty | K23: 1 | T23: =IF(AND(C23<>"",SUM(K23,M23,O23,Q23,S23)=1),"pass",IF(AND(C23="",SUM(K23,M23,O23,Q23,S23)=0),"pass","fail")) -> pass
B24: 11 | C24: General Liability ARL | D24: Proportional | E24: 2001 | F24: 2025 | G24: North America | J24: Casualty | K24: 1 | T24: =IF(AND(C24<>"",SUM(K24,M24,O24,Q24,S24)=1),"pass",IF(AND(C24="",SUM(K24,M24,O24,Q24,S24)=0),"pass","fail")) -> pass
B25: 12 | T25: =IF(AND(C25<>"",SUM(K25,M25,O25,Q25,S25)=1),"pass",IF(AND(C25="",SUM(K25,M25,O25,Q25,S25)=0),"pass","fail")) -> pass
B26: 13 | T26: =IF(AND(C26<>"",SUM(K26,M26,O26,Q26,S26)=1),"pass",IF(AND(C26="",SUM(K26,M26,O26,Q26,S26)=0),"pass","fail")) -> pass
B27: 14 | T27: =IF(AND(C27<>"",SUM(K27,M27,O27,Q27,S27)=1),"pass",IF(AND(C27="",SUM(K27,M27,O27,Q27,S27)=0),"pass","fail")) -> pass
B28: 15 | T28: =IF(AND(C28<>"",SUM(K28,M28,O28,Q28,S28)=1),"pass",IF(AND(C28="",SUM(K28,M28,O28,Q28,S28)=0),"pass","fail")) -> pass
B29: 16 | T29: =IF(AND(C29<>"",SUM(K29,M29,O29,Q29,S29)=1),"pass",IF(AND(C29="",SUM(K29,M29,O29,Q29,S29)=0),"pass","fail")) -> pass
B30: 17 | T30: =IF(AND(C30<>"",SUM(K30,M30,O30,Q30,S30)=1),"pass",IF(AND(C30="",SUM(K30,M30,O30,Q30,S30)=0),"pass","fail")) -> pass
B31: 18 | T31: =IF(AND(C31<>"",SUM(K31,M31,O31,Q31,S31)=1),"pass",IF(AND(C31="",SUM(K31,M31,O31,Q31,S31)=0),"pass","fail")) -> pass
B32: 19 | T32: =IF(AND(C32<>"",SUM(K32,M32,O32,Q32,S32)=1),"pass",IF(AND(C32="",SUM(K32,M32,O32,Q32,S32)=0),"pass","fail")) -> pass
B33: 20 | T33: =IF(AND(C33<>"",SUM(K33,M33,O33,Q33,S33)=1),"pass",IF(AND(C33="",SUM(K33,M33,O33,Q33,S33)=0),"pass","fail")) -> pass
B34: 21 | T34: =IF(AND(C34<>"",SUM(K34,M34,O34,Q34,S34)=1),"pass",IF(AND(C34="",SUM(K34,M34,O34,Q34,S34)=0),"pass","fail")) -> pass
B35: 22 | T35: =IF(AND(C35<>"",SUM(K35,M35,O35,Q35,S35)=1),"pass",IF(AND(C35="",SUM(K35,M35,O35,Q35,S35)=0),"pass","fail")) -> pass
B36: 23 | T36: =IF(AND(C36<>"",SUM(K36,M36,O36,Q36,S36)=1),"pass",IF(AND(C36="",SUM(K36,M36,O36,Q36,S36)=0),"pass","fail")) -> pass
... B213: 200 | T213: =IF(AND(C213<>"",SUM(K213,M213,O213,Q213,S213)=1),"pass",IF(AND(C213="",SUM(K213,M213,O213,Q213,S213)=0),"pass","fail")) -> pass
B216: Define aggregation/grouping of triangles for projection
S217: Cedant Business Segment Names (Optional)
B218: # | C218: Description (free text) | D218: Proportional/Non-proportional | E218: Triangle 1 | F218: Triangle 2 | G218: Region | H218: Country | I218: Re/Ins/Retro | J218: LT LOB 1 (Dropdown List) | K218: LT LOB 1 Allocation | L218: LT LOB 2 (Dropdown List) | M218: LT LOB 2 Allocation | N218: LT LOB 3 (Dropdown List) | O218: LT LOB 3 Allocation | P218: LT LOB 4 (Dropdown List) | Q218: LT LOB 4 Allocation | R218: LT LOB 5 (Dropdown List) | S218: LT LOB 5 Allocation | T218: Allocation Check | U218: Currency | V218: Currency Rate | W218: Segment 1 | X218: Segment 2 | Y218: Segment 3 | Z218: Segment 4 | AA218: Segment 5
B219: 1 | C219: Umbrella Ex C V Starr | D219: Proportional | E219: Umbrella Ex C V Starr | G219: North America | J219: Casualty | K219: 1 | T219: =IF(AND(C219<>"",SUM(K219,M219,O219,Q219,S219)=1),"pass",IF(AND(C219="",SUM(K219,M219,O219,Q219,S219)=0),"pass","fail")) -> pass
B220: 2 | C220: General Liability ex ARL | D220: Proportional | E220: General Liability ex ARL | G220: North America | J220: Casualty | K220: 1 | T220: =IF(AND(C220<>"",SUM(K220,M220,O220,Q220,S220)=1),"pass",IF(AND(C220="",SUM(K220,M220,O220,Q220,S220)=0),"pass","fail")) -> pass
...

Sheet Triangles
G1: Development months
A2: LOB (dropdown) | B2: Type (Incurred / Paid …) | C2: Loss type | D2: Basis (Accident Year / UW Year) | E2: Currency (e.g. USD, GBP …) | F2: Origin Year | G2: =month_first_development -> 6 | H2: =G2+triangle_increments_months -> 18 | I2: =H2+triangle_increments_months -> 30 | J2: =I2+triangle_increments_months -> 42 | K2: =J2+triangle_increments_months -> 54 | L2: =K2+triangle_increments_months -> 66 | M2: =L2+triangle_increments_months -> 78 | N2: =M2+triangle_increments_months -> 90 | O2: =N2+triangle_increments_months -> 102 | ... FA2: =EZ2+triangle_increments_months -> 1806
A3: Umbrella Ex C V Starr | B3: Net Written Premium | C3: All | D3: UW Year | E3: USD | F3: 36892 | G3: 6423779.1 | H3: 6423779.1 | I3: 6423779.1 | J3: 6423779.1 | K3: 6423779.1 | L3: 6423779.1 | M3: 6423779.1 | N3: 6423779.1 | O3: 6423779.1 | P3: 6423779.1 | Q3: 6423779.1 | R3: 6423779.1 | S3: 6423779.1 | T3: 6423779.1 | U3: 6423779.1 | V3: 6423779.1 | W3: 6423779.1 | X3: 6423779.1 | Y3: 6423779.1 | Z3: 6423779.1 | AA3: 6423779.1 | AB3: 6423779.1 | AC3: 6423779.1 | AD3: 6423779.1 | AE3: 6423779.1
A4: Umbrella Ex C V Starr | B4: Net Written Premium | C4: All | D4: UW Year | E4: USD | F4: 37257 | G4: 2293989.5 | H4: 2293989.5 | I4: 2293989.5 | J4: 2293989.5 | K4: 2293989.5 | L4: 2293989.5 | M4: 2293989.5 | N4: 2293989.5 | O4: 2293989.5 | P4: 2293989.5 | Q4: 2293989.5 | R4: 2293989.5 | S4: 2293989.5 | T4: 2293989.5 | U4: 2293989.5 | V4: 2293989.5 | W4: 2293989.5 | X4: 2293989.5 | Y4: 2293989.5 | Z4: 2293989.5 | AA4: 2293989.5 | AB4: 2293989.5 | AC4: 2293989.5 | AD4: 2293989.5
A5: Umbrella Ex C V Starr | B5: Net Written Premium | C5: All | D5: UW Year | E5: USD | F5: 37622 | G5: 4382395.6 | H5: 4382395.6 | I5: 4382395.6 | J5: 4382395.6 | K5: 4382395.6 | L5: 4382395.6 | M5: 4382395.6 | N5: 4382395.6 | O5: 4382395.6 | P5: 4382395.6 | Q5: 4382395.6 | R5: 4382395.6 | S5: 4382395.6 | T5: 4382395.6 | U5: 4382395.6 | V5: 4382395.6 | W5: 4382395.6 | X5: 4382395.6 | Y5: 4382395.6 | Z5: 4382395.6 | AA5: 4382395.6 | AB5: 4382395.6 | AC5: 4382395.6
A6: Umbrella Ex C V Starr | B6: Net Written Premium | C6: All | D6: UW Year | E6: USD | F6: 37987 | G6: 12020857 | H6: 12020857 | I6: 12020857 | J6: 12020857 | K6: 12020857 | L6: 12020857 | M6: 12020857 | N6: 12020857 | O6: 12020857 | P6: 12020857 | Q6: 12020857 | R6: 12020857 | S6: 12020857 | T6: 12020857 | U6: 12020857 | V6: 12020857 | W6: 12020857 | X6: 12020857 | Y6: 12020857 | Z6: 12020857 | AA6: 12020857 | AB6: 12020857
A7: Umbrella Ex C V Starr | B7: Net Written Premium | C7: All | D7: UW Year | E7: USD | F7: 38353 | G7: 13122414 | H7: 13122414 | I7: 13122414 | J7: 13122414 | K7: 13122414 | L7: 13122414 | M7: 13122414 | N7: 13122414 | O7: 13122414 | P7: 13122414 | Q7: 13122414 | R7: 13122414 | S7: 13122414 | T7: 13122414 | U7: 13122414 | V7: 13122414 | W7: 13122414 | X7: 13122414 | Y7: 13122414 | Z7: 13122414 | AA7: 13122414
A8: Umbrella Ex C V Starr | B8: Net Written Premium | C8: All | D8: UW Year | E8: USD | F8: 38718 | G8: 14510011 | H8: 14510011 | I8: 14510011 | J8: 14510011 | K8: 14510011 | L8: 14510011 | M8: 14510011 | N8: 14510011 | O8: 14510011 | P8: 14510011 | Q8: 14510011 | R8: 14510011 | S8: 14510011 | T8: 14510011 | U8: 14510011 | V8: 14510011 | W8: 14510011 | X8: 14510011 | Y8: 14510011 | Z8: 14510011
A9: Umbrella Ex C V Starr | B9: Net Written Premium | C9: All | D9: UW Year | E9: USD | F9: 39083 | G9: 14938715 | H9: 14938715 | I9: 14938715 | J9: 14938715 | K9: 14938715 | L9: 14938715 | M9: 14938715 | N9: 14938715 | O9: 14938715 | P9: 14938715 | Q9: 14938715 | R9: 14938715 | S9: 14938715 | T9: 14938715 | U9: 14938715 | V9: 14938715 | W9: 14938715 | X9: 14938715 | Y9: 14938715
A10: Umbrella Ex C V Starr | B10: Net Written Premium | C10: All | D10: UW Year | E10: USD | F10: 39448 | G10: 15977949 | H10: 15977949 | I10: 15977949 | J10: 15977949 | K10: 15977949 | L10: 15977949 | M10: 15977949 | N10: 15977949 | O10: 15977949 | P10: 15977949 | Q10: 15977949 | R10: 15977949 | S10: 15977949 | T10: 15977949 | U10: 15977949 | V10: 15977949 | W10: 15977949 | X10: 15977949
A11: Umbrella Ex C V Starr | B11: Net Written Premium | C11: All | D11: UW Year | E11: USD | F11: 39814 | G11: 13641854 | H11: 13641854 | I11: 13641854 | J11: 13641854 | K11: 13641854 | L11: 13641854 | M11: 13641854 | N11: 13641854 | O11: 13641854 | P11: 13641854 | Q11: 13641854 | R11: 13641854 | S11: 13641854 | T11: 13641854 | U11: 13641854 | V11: 13641854 | W11: 13641854
A12: Umbrella Ex C V Starr | B12: Net Written Premium | C12: All | D12: UW Year | E12: USD | F12: 40179 | G12: 14844336 | H12: 14844336 | I12: 14844336 | J12: 14844336 | K12: 14844336 | L12: 14844336 | M12: 14844336 | N12: 14844336 | O12: 14844336 | P12: 14844336 | Q12: 14844336 | R12: 14844336 | S12: 14844336 | T12: 14844336 | U12: 14844336 | V12: 14844336
A13: Umbrella Ex C V Starr | B13: Net Written Premium | C13: All | D13: UW Year | E13: USD | F13: 40544 | G13: 13033878 | H13: 13033878 | I13: 13033878 | J13: 13033878 | K13: 13033878 | L13: 13033878 | M13: 13033878 | N13: 13033878 | O13: 13033878 | P13: 13033878 | Q13: 13033878 | R13: 13033878 | S13: 13033878 | T13: 13033878 | U13: 13033878
A14: Umbrella Ex C V Starr | B14: Net Written Premium | C14: All | D14: UW Year | E14: USD | F14: 40909 | G14: 14350697 | H14: 14350697 | I14: 14350697 | J14: 14350697 | K14: 14350697 | L14: 14350697 | M14: 14350697 | N14: 14350697 | O14: 14350697 | P14: 14350697 | Q14: 14350697 | R14: 14350697 | S14: 14350697 | T14: 14350697
A15: Umbrella Ex C V Starr | B15: Net Written Premium | C15: All | D15: UW Year | E15: USD | F15: 41275 | G15: 14692846 | H15: 14692846 | I15: 14692846 | J15: 14692846 | K15: 14692846 | L15: 14692846 | M15: 14692846 | N15: 14692846 | O15: 14692846 | P15: 14692846 | Q15: 14692846 | R15: 14692846 | S15: 14692846
A16: Umbrella Ex C V Starr | B16: Net Written Premium | C16: All | D16: UW Year | E16: USD | F16: 41640 | G16: 21571417 | H16: 21571417 | I16: 21571417 | J16: 21571417 | K16: 21571417 | L16: 21571417 | M16: 21571417 | N16: 21571417 | O16: 21571417 | P16: 21571417 | Q16: 21571417 | R16: 21571417
A17: Umbrella Ex C V Starr | B17: Net Written Premium | C17: All | D17: UW Year | E17: USD | F17: 42005 | G17: 31636740 | H17: 31636740 | I17: 31636740 | J17: 31636740 | K17: 31636740 | L17: 31636740 | M17: 31636740 | N17: 31636740 | O17: 31636740 | P17: 31636740 | Q17: 31636740
A18: Umbrella Ex C V Starr | B18: Net Written Premium | C18: All | D18: UW Year | E18: USD | F18: 42370 | G18: 45216769 | H18: 45216769 | I18: 45216769 | J18: 45216769 | K18: 45216769 | L18: 45216769 | M18: 45216769 | N18: 45216769 | O18: 45216769 | P18: 45216769
A19: Umbrella Ex C V Starr | B19: Net Written Premium | C19: All | D19: UW Year | E19: USD | F19: 42736 | G19: 84475419 | H19: 84475419 | I19: 84475419 | J19: 84475419 | K19: 84475419 | L19: 84475419 | M19: 84475419 | N19: 84475419 | O19: 84475419
A20: Umbrella Ex C V Starr | B20: Net Written Premium | C20: All | D20: UW Year | E20: USD | F20: 43101 | G20: 1.2918805e+08 | H20: 1.2918805e+08 | I20: 1.2918805e+08 | J20: 1.2918805e+08 | K20: 1.2918805e+08 | L20: 1.2918805e+08 | M20: 1.2918805e+08 | N20: 1.2918805e+08
A21: Umbrella Ex C V Starr | B21: Net Written Premium | C21: All | D21: UW Year | E21: USD | F21: 43466 | G21: 1.8996554e+08 | H21: 1.8996554e+08 | I21: 1.8996554e+08 | J21: 1.8996554e+08 | K21: 1.8996554e+08 | L21: 1.8996554e+08 | M21: 1.8996554e+08
A22: Umbrella Ex C V Starr | B22: Net Written Premium | C22: All | D22: UW Year | E22: USD | F22: 43831 | G22: 2.8354491e+08 | H22: 2.8354491e+08 | I22: 2.8354491e+08 | J22: 2.8354491e+08 | K22: 2.8354491e+08 | L22: 2.8354491e+08
A23: Umbrella Ex C V Starr | B23: Net Written Premium | C23: All | D23: UW Year | E23: USD | F23: 44197 | G23: 4.0386135e+08 | H23: 4.0386135e+08 | I23: 4.0386135e+08 | J23: 4.0386135e+08 | K23: 4.0386135e+08
A24: Umbrella Ex C V Starr | B24: Net Written Premium | C24: All | D24: UW Year | E24: USD | F24: 44562 | G24: 5.0969035e+08 | H24: 5.0969035e+08 | I24: 5.0969035e+08 | J24: 5.0969035e+08
A25: Umbrella Ex C V Starr | B25: Net Written Premium | C25: All | D25: UW Year | E25: USD | F25: 44927 | G25: 5.7445655e+08 | H25: 5.7445655e+08 | I25: 5.7445655e+08
A26: Umbrella Ex C V Starr | B26: Net Written Premium | C26: All | D26: UW Year | E26: USD | F26: 45292 | G26: 6.075255e+08 | H26: 6.075255e+08
A27: Umbrella Ex C V Starr | B27: Net Written Premium | C27: All | D27: UW Year | E27: USD | F27: 45658 | G27: 2.6266859e+08
A28: Umbrella Ex C V Starr | B28: Incurred | C28: All | D28: UW Year | E28: USD | F28: 36892 | G28: 0 | H28: 0 | I28: 0 | J28: 1125000 | K28: 1125000 | L28: 1148855.6 | M28: 1298425.8 | N28: 948379.12 | O28: 948379.12 | P28: 948379.12 | Q28: 948379.12 | R28: 948379.12 | S28: 948379.12 | T28: 948379.12 | U28: 948379.12 | V28: 948379.12 | W28: 948379.12 | X28: 948379.12 | Y28: 948381.12 | Z28: 948381.12 | AA28: 948379.12 | AB28: 948379.12 | AC28: 948379.12 | AD28: 948379.12 | AE28: 948379.12
A29: Umbrella Ex C V Starr | B29: Incurred | C29: All | D29: UW Year | E29: USD | F29: 37257 | G29: 0 | H29: 0 | I29: 0 | J29: 0 | K29: 0 | L29: 0 | M29: 0 | N29: 0 | O29: 0 | P29: 0 | Q29: 0 | R29: 0 | S29: 0 | T29: 0 | U29: 0 | V29: 0 | W29: 0 | X29: 0 | Y29: 0 | Z29: 0 | AA29: 0 | AB29: 0 | AC29: 0 | AD29: 0
A30: Umbrella Ex C V Starr | B30: Incurred | C30: All | D30: UW Year | E30: USD | F30: 37622 | G30: 0 | H30: 0 | I30: 1000000 | J30: 1000000 | K30: 1000000 | L30: 1000000 | M30: 1000000 | N30: 1000000 | O30: 1000000 | P30: 1000000 | Q30: 1000000 | R30: 1000000 | S30: 1000000 | T30: 1000000 | U30: 1000000 | V30: 1000000 | W30: 1000000 | X30: 1000000 | Y30: 1000000 | Z30: 1000000 | AA30: 1000000 | AB30: 1000000 | AC30: 1000000
A31: Umbrella Ex C V Starr | B31: Incurred | C31: All | D31: UW Year | E31: USD | F31: 37987 | G31: 0 | H31: 1146861.6 | I31: 1131855.4 | J31: 1506893.8 | K31: 1506893.8 | L31: 1514170.1 | M31: 1514170.1 | N31: 2264170.1 | O31: 2264170.1 | P31: 2264170.1 | Q31: 2264170.1 | R31: 2264170.1 | S31: 2264170.1 | T31: 2264170.1 | U31: 2264170.1 | V31: 2264170.1 | W31: 2264170.1 | X31: 2264170.1 | Y31: 2264170.1 | Z31: 2264170.1 | AA31: 2264170.1 | AB31: 2264170.1
A32: Umbrella Ex C V Starr | B32: Incurred | C32: All | D32: UW Year | E32: USD | F32: 38353 | G32: 0 | H32: 626198.92 | I32: 5107.92 | J32: 15068.81 | K32: 6980.41 | L32: 7274.41 | M32: 7274.41 | N32: 7274.41 | O32: 7274.41 | P32: 7274.41 | Q32: 7274.41 | R32: 7274.41 | S32: 7274.41 | T32: 7274.41 | U32: 7274.41 | V32: 7274.41 | W32: 7274.41 | X32: 7274.41 | Y32: 7274.41 | Z32: 7274.41 | AA32: 7274.41
A33: Umbrella Ex C V Starr | B33: Incurred | C33: All | D33: UW Year | E33: USD | F33: 38718 | G33: 24000 | H33: 26.89 | I33: 4271477 | J33: 5810139.8 | K33: 5860394.1 | L33: 5940633.1 | M33: 5631634 | N33: 5161751.8 | O33: 5162281.7 | P33: 5162281.7 | Q33: 5162567.3 | R33: 5162567.3 | S33: 5162567.3 | T33: 5162567.3 | U33: 5162567.3 | V33: 5162567.3 | W33: 5162567.3 | X33: 5162567.3 | Y33: 5162567.3 | Z33: 5162567.3
A34: Umbrella Ex C V Starr | B34: Incurred | C34: All | D34: UW Year | E34: USD | F34: 39083 | G34: 4500 | H34: 2238617.5 | I34: 2456175.7 | J34: 5041682.8 | K34: 6557920.2 | L34: 8804636.3 | M34: 9808177.2 | N34: 10412177 | O34: 10412177 | P34: 10412177 | Q34: 10412177 | R34: 10412177 | S34: 10412177 | T34: 10412177 | U34: 10412178 | V34: 10412178 | W34: 10412178 | X34: 10412177 | Y34: 10412177
A35: Umbrella Ex C V Starr | B35: Incurred | C35: All | D35: UW Year | E35: USD | F35: 39448 | G35: 1 | H35: 500020 | I35: 350000 | J35: 1356510.4 | K35: 1207305.4 | L35: 3047409.7 | M35: 4958369.8 | N35: 4958369.8 | O35: 7958368.8 | P35: 8958368.8 | Q35: 8958368.8 | R35: 8958368.8 | S35: 8958368.8 | T35: 8958368.8 | U35: 8958368.8 | V35: 8958368.8 | W35: 8958368.8 | X35: 8958368.8
A36: Umbrella Ex C V Starr | B36: Incurred | C36: All | D36: UW Year | E36: USD | F36: 39814 | G36: 0 | H36: 1 | I36: 0 | J36: 253112.5 | K36: 235529.84 | L36: 1562932.6 | M36: 1363121.4 | N36: 1363119.4 | O36: 1363119.4 | P36: 1363119.4 | Q36: 1363119.4 | R36: 1363119.4 | S36: 1363119.4 | T36: 1363119.4 | U36: 1363119.4 | V36: 1363119.4 | W36: 1363119.4
A37: Umbrella Ex C V Starr | B37: Incurred | C37: All | D37: UW Year | E37: USD | F37: 40179 | G37: 0 | H37: 1426155 | I37: 1236381.6 | J37: 1739334.6 | K37: 4936085.2 | L37: 4759236.5 | M37: 4760021.2 | N37: 4760054.2 | O37: 4760032.2 | P37: 4760021.2 | Q37: 4760021.2 | R37: 4760121.2 | S37: 4760021.2 | T37: 4760021.2 | U37: 4760021.2 | V37: 4760021.2
A38: Umbrella Ex C V Starr | B38: Incurred | C38: All | D38: UW Year | E38: USD | F38: 40544 | G38: 127 | H38: 6522 | I38: 2618753.2 | J38: 5395097.3 | K38: 6215757.9 | L38: 6790837 | M38: 8290799 | N38: 8295874 | O38: 8295869 | P38: 8295839 | Q38: 8295832 | R38: 7044798 | S38: 7044799 | T38: 11309876 | U38: 11308460
A39: Umbrella Ex C V Starr | B39: Incurred | C39: All | D39: UW Year | E39: USD | F39: 40909 | G39: 0 | H39: 260910.75 | I39: 256610.91 | J39: 256512.91 | K39: 2707011.9 | L39: 7135086.4 | M39: 9412908.4 | N39: 11301424 | O39: 11301424 | P39: 11301393 | Q39: 11281393 | R39: 11031724 | S39: 11031725 | T39: 11031723
A40: Umbrella Ex C V Starr | B40: Incurred | C40: All | D40: UW Year | E40: USD | F40: 41275 | G40: 0 | H40: 5037495 | I40: 5118925.6 | J40: 5133700.1 | K40: 5213669.4 | L40: 7209234.3 | M40: 6601360.4 | N40: 6601360.4 | O40: 6601416.4 | P40: 6601416.4 | Q40: 6601417.4 | R40: 6602812 | S40: 6605812
...

Sheet Projections
A1: Longtail Reference | B1: UW Year | C1: Ultimate GG Prem ($M) | D1: Latest GG Prem ($M) | E1: Latest GN Prem ($M) | F1: Acq Cost | G1: Cedant Provided Ultimate Loss Ratio | H1: Cedant Provided CoV | I1: Rate Change | J1: Inflation | K1: Historic Year Check | L1: Current Year Check | M1: Min Origin Year: | N1: =YEAR(triangle_start_date) -> 2001 | O1: Max Origin Year: | P1: =YEAR(current_date)-1 -> 2025 | R1: Checks
A2: Auto Liability | B2: 2001 | C2: 8.1366889 | D2: 8.1366889 | E2: 8.1366889 | K2: =IF(OR(B2<$N$1,B2>$P$1),"fail","pass") -> pass | L2: =IFERROR(IF(AND(MATCH(A2,Projection_classes,0),YEAR(current_date)=Projections!B2),"pass","fail"),"") -> fail | R2: =IF(S2>0, "RATE CHANGE COLUMN CONTAINS ERROR VALUES. PLEASE SET THEM TO 0s", "Rate Change column no error values.") -> Rate Change column no error values. | S2: {=SUMPRODUCT(--ISERROR(I2:I1000))} -> 0
A3: Auto Liability | B3: 2002 | C3: 8.0484384 | D3: 8.0484384 | E3: 8.0484384 | K3: =IF(OR(B3<$N$1,B3>$P$1),"fail","pass") -> pass | L3: =IFERROR(IF(AND(MATCH(A3,Projection_classes,0),YEAR(current_date)=Projections!B3),"pass","fail"),"") -> fail | R3: =IF(S3>0, "INFLATION COLUMN CONTAINS ERROR VALUES. PLEASE SET THEM TO 0s", "Inflation column no error values.") -> Inflation column no error values. | S3: {=SUMPRODUCT(--ISERROR(J2:J1000))} -> 0
A4: Auto Liability | B4: 2003 | C4: 11.940716 | D4: 11.940716 | E4: 11.940716 | K4: =IF(OR(B4<$N$1,B4>$P$1),"fail","pass") -> pass | L4: =IFERROR(IF(AND(MATCH(A4,Projection_classes,0),YEAR(current_date)=Projections!B4),"pass","fail"),"") -> fail
A5: Auto Liability | B5: 2004 | C5: 16.579211 | D5: 16.579211 | E5: 16.579211 | K5: =IF(OR(B5<$N$1,B5>$P$1),"fail","pass") -> pass | L5: =IFERROR(IF(AND(MATCH(A5,Projection_classes,0),YEAR(current_date)=Projections!B5),"pass","fail"),"") -> fail
A6: Auto Liability | B6: 2005 | C6: 18.825765 | D6: 18.825765 | E6: 18.825765 | K6: =IF(OR(B6<$N$1,B6>$P$1),"fail","pass") -> pass | L6: =IFERROR(IF(AND(MATCH(A6,Projection_classes,0),YEAR(current_date)=Projections!B6),"pass","fail"),"") -> fail | R6: Mandatory
A7: Auto Liability | B7: 2006 | C7: 19.523392 | D7: 19.523392 | E7: 19.523392 | K7: =IF(OR(B7<$N$1,B7>$P$1),"fail","pass") -> pass | L7: =IFERROR(IF(AND(MATCH(A7,Projection_classes,0),YEAR(current_date)=Projections!B7),"pass","fail"),"") -> fail | R7: Optional
A8: Auto Liability | B8: 2007 | C8: 20.315469 | D8: 20.315469 | E8: 20.315469 | I8: -0.0090413677 | J8: 0.087733472 | K8: =IF(OR(B8<$N$1,B8>$P$1),"fail","pass") -> pass | L8: =IFERROR(IF(AND(MATCH(A8,Projection_classes,0),YEAR(current_date)=Projections!B8),"pass","fail"),"") -> fail
A9: Auto Liability | B9: 2008 | C9: 34.46956 | D9: 34.46956 | E9: 34.46956 | I9: -0.050167356 | J9: 0.087236473 | K9: =IF(OR(B9<$N$1,B9>$P$1),"fail","pass") -> pass | L9: =IFERROR(IF(AND(MATCH(A9,Projection_classes,0),YEAR(current_date)=Projections!B9),"pass","fail"),"") -> fail
A10: Auto Liability | B10: 2009 | C10: 32.611351 | D10: 32.611351 | E10: 32.611351 | I10: -0.020910608 | J10: 0.075952758 | K10: =IF(OR(B10<$N$1,B10>$P$1),"fail","pass") -> pass | L10: =IFERROR(IF(AND(MATCH(A10,Projection_classes,0),YEAR(current_date)=Projections!B10),"pass","fail"),"") -> fail
A11: Auto Liability | B11: 2010 | C11: 23.565427 | D11: 23.565427 | E11: 23.565427 | I11: -0.00029274553 | J11: 0.071912051 | K11: =IF(OR(B11<$N$1,B11>$P$1),"fail","pass") -> pass | L11: =IFERROR(IF(AND(MATCH(A11,Projection_classes,0),YEAR(current_date)=Projections!B11),"pass","fail"),"") -> fail
A12: Auto Liability | B12: 2011 | C12: 17.298426 | D12: 17.298426 | E12: 17.298426 | I12: -0.005822788 | J12: 0.075227489 | K12: =IF(OR(B12<$N$1,B12>$P$1),"fail","pass") -> pass | L12: =IFERROR(IF(AND(MATCH(A12,Projection_classes,0),YEAR(current_date)=Projections!B12),"pass","fail"),"") -> fail
A13: Auto Liability | B13: 2012 | C13: 9.3987519 | D13: 9.3987519 | E13: 9.3987519 | I13: -0.0021910283 | J13: 0.074006983 | K13: =IF(OR(B13<$N$1,B13>$P$1),"fail","pass") -> pass | L13: =IFERROR(IF(AND(MATCH(A13,Projection_classes,0),YEAR(current_date)=Projections!B13),"pass","fail"),"") -> fail
A14: Auto Liability | B14: 2013 | C14: 11.234086 | D14: 11.234086 | E14: 11.234086 | I14: -0.0049192179 | J14: 0.069322035 | K14: =IF(OR(B14<$N$1,B14>$P$1),"fail","pass") -> pass | L14: =IFERROR(IF(AND(MATCH(A14,Projection_classes,0),YEAR(current_date)=Projections!B14),"pass","fail"),"") -> fail
A15: Auto Liability | B15: 2014 | C15: 19.154309 | D15: 19.154309 | E15: 19.154309 | I15: -0.016754683 | J15: 0.067044285 | K15: =IF(OR(B15<$N$1,B15>$P$1),"fail","pass") -> pass | L15: =IFERROR(IF(AND(MATCH(A15,Projection_classes,0),YEAR(current_date)=Projections!B15),"pass","fail"),"") -> fail
A16: Auto Liability | B16: 2015 | C16: 29.321088 | D16: 29.321088 | E16: 29.321088 | I16: -0.013229945 | J16: 0.069245491 | K16: =IF(OR(B16<$N$1,B16>$P$1),"fail","pass") -> pass | L16: =IFERROR(IF(AND(MATCH(A16,Projection_classes,0),YEAR(current_date)=Projections!B16),"pass","fail"),"") -> fail
A17: Auto Liability | B17: 2016 | C17: 34.072388 | D17: 34.072388 | E17: 34.072388 | I17: -0.0047554079 | J17: 0.069561773 | K17: =IF(OR(B17<$N$1,B17>$P$1),"fail","pass") -> pass | L17: =IFERROR(IF(AND(MATCH(A17,Projection_classes,0),YEAR(current_date)=Projections!B17),"pass","fail"),"") -> fail
A18: Auto Liability | B18: 2017 | C18: 52.802136 | D18: 52.802136 | E18: 52.802136 | I18: -0.0051204854 | J18: 0.079010008 | K18: =IF(OR(B18<$N$1,B18>$P$1),"fail","pass") -> pass | L18: =IFERROR(IF(AND(MATCH(A18,Projection_classes,0),YEAR(current_date)=Projections!B18),"pass","fail"),"") -> fail
A19: Auto Liability | B19: 2018 | C19: 89.615987 | D19: 89.615987 | E19: 89.615987 | I19: 0.012497099 | J19: 0.078738372 | K19: =IF(OR(B19<$N$1,B19>$P$1),"fail","pass") -> pass | L19: =IFERROR(IF(AND(MATCH(A19,Projection_classes,0),YEAR(current_date)=Projections!B19),"pass","fail"),"") -> fail
... A25: Auto Liability | B25: 2024 | C25: 262.54838 | D25: 262.54838 | E25: 262.54838 | I25: 0.077167475 | J25: 0.084594526 | K25: =IF(OR(B25<$N$1,B25>$P$1),"fail","pass") -> pass | L25: =IFERROR(IF(AND(MATCH(A25,Projection_classes,0),YEAR(current_date)=Projections!B25),"pass","fail"),"") -> fail
A26: Auto Liability | B26: 2025 | C26: 106.46804 | D26: 106.46804 | E26: 106.46804 | K26: =IF(OR(B26<$N$1,B26>$P$1),"fail","pass") -> pass | L26: =IFERROR(IF(AND(MATCH(A26,Projection_classes,0),YEAR(current_date)=Projections!B26),"pass","fail"),"") -> fail
A27: Auto Liability | B27: 2026 | C27: 246.43301 | D27: 0 | E27: 0 | K27: =IF(OR(B27<$N$1,B27>$P$1),"fail","pass") -> fail | L27: =IFERROR(IF(AND(MATCH(A27,Projection_classes,0),YEAR(current_date)=Projections!B27),"pass","fail"),"") -> pass
A28: California Workers Compensation | B28: 2001 | C28: 189.71905 | D28: 189.71905 | E28: 189.71905 | K28: =IF(OR(B28<$N$1,B28>$P$1),"fail","pass") -> pass | L28: =IFERROR(IF(AND(MATCH(A28,Projection_classes,0),YEAR(current_date)=Projections!B28),"pass","fail"),"") -> fail
A29: California Workers Compensation | B29: 2002 | C29: 388.93941 | D29: 388.93941 | E29: 388.93941 | K29: =IF(OR(B29<$N$1,B29>$P$1),"fail","pass") -> pass | L29: =IFERROR(IF(AND(MATCH(A29,Projection_classes,0),YEAR(current_date)=Projections!B29),"pass","fail"),"") -> fail
A30: California Workers Compensation | B30: 2003 | C30: 575.05219 | D30: 575.05219 | E30: 575.05219 | K30: =IF(OR(B30<$N$1,B30>$P$1),"fail","pass") -> pass | L30: =IFERROR(IF(AND(MATCH(A30,Projection_classes,0),YEAR(current_date)=Projections!B30),"pass","fail"),"") -> fail
A31: California Workers Compensation | B31: 2004 | C31: 576.24932 | D31: 576.24932 | E31: 576.24932 | K31: =IF(OR(B31<$N$1,B31>$P$1),"fail","pass") -> pass | L31: =IFERROR(IF(AND(MATCH(A31,Projection_classes,0),YEAR(current_date)=Projections!B31),"pass","fail"),"") -> fail
A32: California Workers Compensation | B32: 2005 | C32: 296.19873 | D32: 296.19873 | E32: 296.19873 | K32: =IF(OR(B32<$N$1,B32>$P$1),"fail","pass") -> pass | L32: =IFERROR(IF(AND(MATCH(A32,Projection_classes,0),YEAR(current_date)=Projections!B32),"pass","fail"),"") -> fail
A33: California Workers Compensation | B33: 2006 | C33: 192.98273 | D33: 192.98273 | E33: 192.98273 | K33: =IF(OR(B33<$N$1,B33>$P$1),"fail","pass") -> pass | L33: =IFERROR(IF(AND(MATCH(A33,Projection_classes,0),YEAR(current_date)=Projections!B33),"pass","fail"),"") -> fail
A34: California Workers Compensation | B34: 2007 | C34: 137.97028 | D34: 137.97028 | E34: 137.97028 | K34: =IF(OR(B34<$N$1,B34>$P$1),"fail","pass") -> pass | L34: =IFERROR(IF(AND(MATCH(A34,Projection_classes,0),YEAR(current_date)=Projections!B34),"pass","fail"),"") -> fail
A35: California Workers Compensation | B35: 2008 | C35: 108.99175 | D35: 108.99175 | E35: 108.99175 | K35: =IF(OR(B35<$N$1,B35>$P$1),"fail","pass") -> pass | L35: =IFERROR(IF(AND(MATCH(A35,Projection_classes,0),YEAR(current_date)=Projections!B35),"pass","fail"),"") -> fail
A36: California Workers Compensation | B36: 2009 | C36: 161.95013 | D36: 161.95013 | E36: 161.95013 | K36: =IF(OR(B36<$N$1,B36>$P$1),"fail","pass") -> pass | L36: =IFERROR(IF(AND(MATCH(A36,Projection_classes,0),YEAR(current_date)=Projections!B36),"pass","fail"),"") -> fail
A37: California Workers Compensation | B37: 2010 | C37: 215.04545 | D37: 215.04545 | E37: 215.04545 | K37: =IF(OR(B37<$N$1,B37>$P$1),"fail","pass") -> pass | L37: =IFERROR(IF(AND(MATCH(A37,Projection_classes,0),YEAR(current_date)=Projections!B37),"pass","fail"),"") -> fail
... A59: Canada Casualty | B59: 2006 | C59: 0 | D59: 0 | E59: 0 | K59: =IF(OR(B59<$N$1,B59>$P$1),"fail","pass") -> pass | L59: =IFERROR(IF(AND(MATCH(A59,Projection_classes,0),YEAR(current_date)=Projections!B59),"pass","fail"),"") -> fail
A60: Canada Casualty | B60: 2007 | C60: 0 | D60: 0 | E60: 0 | I60: -0.0090413677 | J60: 0.087733472 | K60: =IF(OR(B60<$N$1,B60>$P$1),"fail","pass") -> pass | L60: =IFERROR(IF(AND(MATCH(A60,Projection_classes,0),YEAR(current_date)=Projections!B60),"pass","fail"),"") -> fail
A61: Canada Casualty | B61: 2008 | C61: 0 | D61: 0 | E61: 0 | I61: -0.050167356 | J61: 0.087236473 | K61: =IF(OR(B61<$N$1,B61>$P$1),"fail","pass") -> pass | L61: =IFERROR(IF(AND(MATCH(A61,Projection_classes,0),YEAR(current_date)=Projections!B61),"pass","fail"),"") -> fail
A62: Canada Casualty | B62: 2009 | C62: 0 | D62: 0 | E62: 0 | I62: -0.020910608 | J62: 0.075952758 | K62: =IF(OR(B62<$N$1,B62>$P$1),"fail","pass") -> pass | L62: =IFERROR(IF(AND(MATCH(A62,Projection_classes,0),YEAR(current_date)=Projections!B62),"pass","fail"),"") -> fail
A63: Canada Casualty | B63: 2010 | C63: 0 | D63: 0 | E63: 0 | I63: -0.00029274553 | J63: 0.071912051 | K63: =IF(OR(B63<$N$1,B63>$P$1),"fail","pass") -> pass | L63: =IFERROR(IF(AND(MATCH(A63,Projection_classes,0),YEAR(current_date)=Projections!B63),"pass","fail"),"") -> fail
A64: Canada Casualty | B64: 2011 | C64: 5.599828 | D64: 5.599828 | E64: 5.599828 | I64: -0.005822788 | J64: 0.075227489 | K64: =IF(OR(B64<$N$1,B64>$P$1),"fail","pass") -> pass | L64: =IFERROR(IF(AND(MATCH(A64,Projection_classes,0),YEAR(current_date)=Projections!B64),"pass","fail"),"") -> fail
A65: Canada Casualty | B65: 2012 | C65: 13.658783 | D65: 13.658783 | E65: 13.658783 | I65: -0.0021910283 | J65: 0.074006983 | K65: =IF(OR(B65<$N$1,B65>$P$1),"fail","pass") -> pass | L65: =IFERROR(IF(AND(MATCH(A65,Projection_classes,0),YEAR(current_date)=Projections!B65),"pass","fail"),"") -> fail
A66: Canada Casualty | B66: 2013 | C66: 15.784148 | D66: 15.784148 | E66: 15.784148 | I66: -0.0049192179 | J66: 0.069322035 | K66: =IF(OR(B66<$N$1,B66>$P$1),"fail","pass") -> pass | L66: =IFERROR(IF(AND(MATCH(A66,Projection_classes,0),YEAR(current_date)=Projections!B66),"pass","fail"),"") -> fail
...

Sheet admin
A1: template_version | B1: 6

Sheet Other
A1: template_version | B1: 9

Sheet <>

Sheet Example - Parameters
B3: Triangle Shape Parameters | E3: guide | F3: Checks
C4: Triangle start (t=0) date | D4: 38718 | E4: YYYY-MM-DD | F4: =triangle_start_date='Example - Triangles'!F3 -> TRUE | H4: Mandatory
C5: Month of first development | D5: 9 | E5: first month in triangle | H5: Optional
C6: Development period increments (months) | D6: 12 | E6: triangle increments (column)
C7: Origin period increments (months) | D7: 12 | E7: triangle increments (row)
C8: Month of final development | D8: 237 | E8: Latest month in the largest triangle | F8: =IF(ISERROR(MATCH(month_final_development,'Example - Triangles'!$G$2:$FA$2, 0)), "Can't find this development month in triangle. Please be consistent with Triangle.", "OK") -> OK
C9: Inception Date | D9: 46023 | E9: YYYY-MM-DD
C10: Expiry Date | D10: 46387 | E10: YYYY-MM-DD
B11: Triangular data list (LOB/Class)
Q12: Cedant Business Segment Names (Optional)
B13: # | C13: Triangle Name | D13: Proportional/Non-proportional | E13: Start Year | F13: End Year | G13: Region | H13: Country | I13: Re/Ins/Retro | J13: LT LOB 1 (Dropdown List) | K13: LT LOB 1 Allocation | L13: LT LOB 2 (Dropdown List) | M13: LT LOB 2 Allocation | N13: LT LOB 3 (Dropdown List) | O13: LT LOB 3 Allocation | P13: LT LOB 4 (Dropdown List) | Q13: LT LOB 4 Allocation | R13: LT LOB 5 (Dropdown List) | S13: LT LOB 5 Allocation | T13: Allocation Check | U13: Currency | V13: Currency Rate | W13: Segment 1 | X13: Segment 2 | Y13: Segment 3 | Z13: Segment 4 | AA13: Segment 5 | AB13: Premium Triangle Source | AC13: Incurred Triangle Source | AD13: Paid Triangle Source | AE13: Ultimate Triangle Source
B14: 1 | C14: Professional Lines | D14: Mixed | E14: 2006 | F14: 2025 | G14: Worldwide | H14: Multi-country | I14: Retrocession | J14: Professional Liability | K14: 1 | T14: =IF(AND(C14<>"",SUM(K14,M14,O14,Q14,S14)=1),"pass",IF(AND(C14="",SUM(K14,M14,O14,Q14,S14)=0),"pass","fail")) -> pass | AB14: Cedant provided | AC14: Cedant provided | AD14: Cedant provided
B15: 2 | C15: Liability | D15: Mixed | E15: 2006 | F15: 2025 | G15: Worldwide | H15: Multi-country | I15: Retrocession | J15: Casualty | K15: 1 | T15: =IF(AND(C15<>"",SUM(K15,M15,O15,Q15,S15)=1),"pass",IF(AND(C15="",SUM(K15,M15,O15,Q15,S15)=0),"pass","fail")) -> pass | AB15: Cedant provided | AC15: Cedant provided | AD15: Cedant provided
B16: 3 | C16: Credit & Surety | D16: Mixed | E16: 2006 | F16: 2025 | G16: Worldwide | H16: Multi-country | I16: Retrocession | J16: Fidelity & Surety | K16: 1 | T16: =IF(AND(C16<>"",SUM(K16,M16,O16,Q16,S16)=1),"pass",IF(AND(C16="",SUM(K16,M16,O16,Q16,S16)=0),"pass","fail")) -> pass | AB16: Cedant provided | AC16: Cedant provided | AD16: Cedant provided
B17: 4 | C17: Motor NP | D17: Non Proportional | E17: 2006 | F17: 2025 | G17: Worldwide ex US | H17: Multi-country | I17: Retrocession | J17: Motor | K17: 1 | T17: =IF(AND(C17<>"",SUM(K17,M17,O17,Q17,S17)=1),"pass",IF(AND(C17="",SUM(K17,M17,O17,Q17,S17)=0),"pass","fail")) -> pass | AB17: Cedant provided | AC17: Cedant provided | AD17: Cedant provided
B18: 5 | C18: Motor PR | D18: Proportional | E18: 2006 | F18: 2025 | G18: Worldwide ex US | H18: Multi-country | I18: Retrocession | J18: Motor | K18: 1 | T18: =IF(AND(C18<>"",SUM(K18,M18,O18,Q18,S18)=1),"pass",IF(AND(C18="",SUM(K18,M18,O18,Q18,S18)=0),"pass","fail")) -> pass | AB18: Cedant provided | AC18: Cedant provided | AD18: Cedant provided
B19: 6 | C19: Cyber | D19: Mixed | E19: 2006 | F19: 2025 | G19: Worldwide | H19: Multi-country | I19: Retrocession | J19: Cyber | K19: 1 | T19: =IF(AND(C19<>"",SUM(K19,M19,O19,Q19,S19)=1),"pass",IF(AND(C19="",SUM(K19,M19,O19,Q19,S19)=0),"pass","fail")) -> pass | AB19: Cedant provided | AC19: Cedant provided | AD19: Cedant provided
B20: 7 | T20: =IF(AND(C20<>"",SUM(K20,M20,O20,Q20,S20)=1),"pass",IF(AND(C20="",SUM(K20,M20,O20,Q20,S20)=0),"pass","fail")) -> pass
B21: 8 | T21: =IF(AND(C21<>"",SUM(K21,M21,O21,Q21,S21)=1),"pass",IF(AND(C21="",SUM(K21,M21,O21,Q21,S21)=0),"pass","fail")) -> pass
B22: 9 | T22: =IF(AND(C22<>"",SUM(K22,M22,O22,Q22,S22)=1),"pass",IF(AND(C22="",SUM(K22,M22,O22,Q22,S22)=0),"pass","fail")) -> pass
B23: 10 | T23: =IF(AND(C23<>"",SUM(K23,M23,O23,Q23,S23)=1),"pass",IF(AND(C23="",SUM(K23,M23,O23,Q23,S23)=0),"pass","fail")) -> pass
B24: 11 | T24: =IF(AND(C24<>"",SUM(K24,M24,O24,Q24,S24)=1),"pass",IF(AND(C24="",SUM(K24,M24,O24,Q24,S24)=0),"pass","fail")) -> pass
B25: 12 | T25: =IF(AND(C25<>"",SUM(K25,M25,O25,Q25,S25)=1),"pass",IF(AND(C25="",SUM(K25,M25,O25,Q25,S25)=0),"pass","fail")) -> pass
B26: 13 | T26: =IF(AND(C26<>"",SUM(K26,M26,O26,Q26,S26)=1),"pass",IF(AND(C26="",SUM(K26,M26,O26,Q26,S26)=0),"pass","fail")) -> pass
B27: 14 | T27: =IF(AND(C27<>"",SUM(K27,M27,O27,Q27,S27)=1),"pass",IF(AND(C27="",SUM(K27,M27,O27,Q27,S27)=0),"pass","fail")) -> pass
B28: 15 | T28: =IF(AND(C28<>"",SUM(K28,M28,O28,Q28,S28)=1),"pass",IF(AND(C28="",SUM(K28,M28,O28,Q28,S28)=0),"pass","fail")) -> pass
B29: 16 | T29: =IF(AND(C29<>"",SUM(K29,M29,O29,Q29,S29)=1),"pass",IF(AND(C29="",SUM(K29,M29,O29,Q29,S29)=0),"pass","fail")) -> pass
B30: 17 | T30: =IF(AND(C30<>"",SUM(K30,M30,O30,Q30,S30)=1),"pass",IF(AND(C30="",SUM(K30,M30,O30,Q30,S30)=0),"pass","fail")) -> pass
B31: 18 | T31: =IF(AND(C31<>"",SUM(K31,M31,O31,Q31,S31)=1),"pass",IF(AND(C31="",SUM(K31,M31,O31,Q31,S31)=0),"pass","fail")) -> pass
... B35: 22 | T35: =IF(AND(C35<>"",SUM(K35,M35,O35,Q35,S35)=1),"pass",IF(AND(C35="",SUM(K35,M35,O35,Q35,S35)=0),"pass","fail")) -> pass
B36: 23 | R36: =IF(AND(C36<>"",SUM(I36,K36,M36,O36,Q36)=1),"pass",IF(AND(C36="",SUM(I36,K36,M36,O36,Q36)=0),"pass","fail")) -> pass
B37: 24 | R37: =IF(AND(C37<>"",SUM(I37,K37,M37,O37,Q37)=1),"pass",IF(AND(C37="",SUM(I37,K37,M37,O37,Q37)=0),"pass","fail")) -> pass
B38: 25
B39: 26
B40: 27
B41: 28
B42: 29
B43: 30
B44: 31
B45: 32
...

Sheet Example - Triangles
G1: Development months
A2: LOB (dropdown) | B2: Type (Incurred / Paid …) | C2: Loss type | D2: Basis (Accident Year / UW Year) | E2: Currency (e.g. USD, GBP …) | F2: Origin Year | G2: =month_first_development -> 6 | H2: =G2+triangle_increments_months -> 18 | I2: =H2+triangle_increments_months -> 30 | J2: =I2+triangle_increments_months -> 42 | K2: =J2+triangle_increments_months -> 54 | L2: =K2+triangle_increments_months -> 66 | M2: =L2+triangle_increments_months -> 78 | N2: =M2+triangle_increments_months -> 90 | O2: =N2+triangle_increments_months -> 102 | ... FA2: =EZ2+triangle_increments_months -> 1806
A3: Professional Lines | B3: Net Written Premium | C3: All | D3: UW Year | E3: USD | F3: =triangle_start_date -> 36892 | G3: 1000000 | H3: 2000000 | I3: 2000000 | J3: 2000000 | K3: 2000000 | L3: 2000000 | M3: 2000000 | N3: 2000000 | O3: 2000000 | P3: 2000000 | Q3: 2000000 | R3: 2000000 | S3: 2000000 | T3: 2000000 | U3: 2000000 | V3: 2000000 | W3: 2000000 | X3: 2000000 | Y3: 2000000 | Z3: 2000000
A4: Professional Lines | B4: Net Written Premium | C4: All | D4: UW Year | E4: USD | F4: =EDATE(F3,12) -> 37257 | G4: 1000000 | H4: 2000000 | I4: 2000000 | J4: 2000000 | K4: 2000000 | L4: 2000000 | M4: 2000000 | N4: 2000000 | O4: 2000000 | P4: 2000000 | Q4: 2000000 | R4: 2000000 | S4: 2000000 | T4: 2000000 | U4: 2000000 | V4: 2000000 | W4: 2000000 | X4: 2000000 | Y4: 2000000
A5: Professional Lines | B5: Net Written Premium | C5: All | D5: UW Year | E5: USD | F5: =EDATE(F4,12) -> 37622 | G5: 1000000 | H5: 2000000 | I5: 2000000 | J5: 2000000 | K5: 2000000 | L5: 2000000 | M5: 2000000 | N5: 2000000 | O5: 2000000 | P5: 2000000 | Q5: 2000000 | R5: 2000000 | S5: 2000000 | T5: 2000000 | U5: 2000000 | V5: 2000000 | W5: 2000000 | X5: 2000000
A6: Professional Lines | B6: Net Written Premium | C6: All | D6: UW Year | E6: USD | F6: =EDATE(F5,12) -> 37987 | G6: 1000000 | H6: 2000000 | I6: 2000000 | J6: 2000000 | K6: 2000000 | L6: 2000000 | M6: 2000000 | N6: 2000000 | O6: 2000000 | P6: 2000000 | Q6: 2000000 | R6: 2000000 | S6: 2000000 | T6: 2000000 | U6: 2000000 | V6: 2000000 | W6: 2000000
A7: Professional Lines | B7: Net Written Premium | C7: All | D7: UW Year | E7: USD | F7: =EDATE(F6,12) -> 38353 | G7: 1000000 | H7: 2000000 | I7: 2000000 | J7: 2000000 | K7: 2000000 | L7: 2000000 | M7: 2000000 | N7: 2000000 | O7: 2000000 | P7: 2000000 | Q7: 2000000 | R7: 2000000 | S7: 2000000 | T7: 2000000 | U7: 2000000 | V7: 2000000
A8: Professional Lines | B8: Net Written Premium | C8: All | D8: UW Year | E8: USD | F8: =EDATE(F7,12) -> 38718 | G8: 1000000 | H8: 2000000 | I8: 2000000 | J8: 2000000 | K8: 2000000 | L8: 2000000 | M8: 2000000 | N8: 2000000 | O8: 2000000 | P8: 2000000 | Q8: 2000000 | R8: 2000000 | S8: 2000000 | T8: 2000000 | U8: 2000000
A9: Professional Lines | B9: Net Written Premium | C9: All | D9: UW Year | E9: USD | F9: =EDATE(F8,12) -> 39083 | G9: 1000000 | H9: 2000000 | I9: 2000000 | J9: 2000000 | K9: 2000000 | L9: 2000000 | M9: 2000000 | N9: 2000000 | O9: 2000000 | P9: 2000000 | Q9: 2000000 | R9: 2000000 | S9: 2000000 | T9: 2000000
A10: Professional Lines | B10: Net Written Premium | C10: All | D10: UW Year | E10: USD | F10: =EDATE(F9,12) -> 39448 | G10: 1000000 | H10: 2000000 | I10: 2000000 | J10: 2000000 | K10: 2000000 | L10: 2000000 | M10: 2000000 | N10: 2000000 | O10: 2000000 | P10: 2000000 | Q10: 2000000 | R10: 2000000 | S10: 2000000
A11: Professional Lines | B11: Net Written Premium | C11: All | D11: UW Year | E11: USD | F11: =EDATE(F10,12) -> 39814 | G11: 1000000 | H11: 2000000 | I11: 2000000 | J11: 2000000 | K11: 2000000 | L11: 2000000 | M11: 2000000 | N11: 2000000 | O11: 2000000 | P11: 2000000 | Q11: 2000000 | R11: 2000000
A12: Professional Lines | B12: Net Written Premium | C12: All | D12: UW Year | E12: USD | F12: =EDATE(F11,12) -> 40179 | G12: 1000000 | H12: 2000000 | I12: 2000000 | J12: 2000000 | K12: 2000000 | L12: 2000000 | M12: 2000000 | N12: 2000000 | O12: 2000000 | P12: 2000000 | Q12: 2000000
A13: Professional Lines | B13: Net Written Premium | C13: All | D13: UW Year | E13: USD | F13: =EDATE(F12,12) -> 40544 | G13: 1000000 | H13: 2000000 | I13: 2000000 | J13: 2000000 | K13: 2000000 | L13: 2000000 | M13: 2000000 | N13: 2000000 | O13: 2000000 | P13: 2000000
A14: Professional Lines | B14: Net Written Premium | C14: All | D14: UW Year | E14: USD | F14: =EDATE(F13,12) -> 40909 | G14: 1000000 | H14: 2000000 | I14: 2000000 | J14: 2000000 | K14: 2000000 | L14: 2000000 | M14: 2000000 | N14: 2000000 | O14: 2000000
A15: Professional Lines | B15: Net Written Premium | C15: All | D15: UW Year | E15: USD | F15: =EDATE(F14,12) -> 41275 | G15: 1000000 | H15: 2000000 | I15: 2000000 | J15: 2000000 | K15: 2000000 | L15: 2000000 | M15: 2000000 | N15: 2000000
A16: Professional Lines | B16: Net Written Premium | C16: All | D16: UW Year | E16: USD | F16: =EDATE(F15,12) -> 41640 | G16: 1000000 | H16: 2000000 | I16: 2000000 | J16: 2000000 | K16: 2000000 | L16: 2000000 | M16: 2000000
A17: Professional Lines | B17: Net Written Premium | C17: All | D17: UW Year | E17: USD | F17: =EDATE(F16,12) -> 42005 | G17: 1000000 | H17: 2000000 | I17: 2000000 | J17: 2000000 | K17: 2000000 | L17: 2000000
A18: Professional Lines | B18: Net Written Premium | C18: All | D18: UW Year | E18: USD | F18: =EDATE(F17,12) -> 42370 | G18: 1000000 | H18: 2000000 | I18: 2000000 | J18: 2000000 | K18: 2000000
A19: Professional Lines | B19: Net Written Premium | C19: All | D19: UW Year | E19: USD | F19: =EDATE(F18,12) -> 42736 | G19: 1000000 | H19: 2000000 | I19: 2000000 | J19: 2000000
A20: Professional Lines | B20: Net Written Premium | C20: All | D20: UW Year | E20: USD | F20: =EDATE(F19,12) -> 43101 | G20: 1000000 | H20: 2000000 | I20: 2000000
A21: Professional Lines | B21: Net Written Premium | C21: All | D21: UW Year | E21: USD | F21: =EDATE(F20,12) -> 43466 | G21: 1000000 | H21: 2000000
A22: Professional Lines | B22: Net Written Premium | C22: All | D22: UW Year | E22: USD | F22: =EDATE(F21,12) -> 43831 | G22: 1000000
A24: Liability | B24: Net Written Premium | C24: All | D24: UW Year | E24: USD | F24: =triangle_start_date -> 36892 | G24: 1000000 | H24: 2000000 | I24: 2000000 | J24: 2000000 | K24: 2000000 | L24: 2000000 | M24: 2000000 | N24: 2000000 | O24: 2000000 | P24: 2000000 | Q24: 2000000 | R24: 2000000 | S24: 2000000 | T24: 2000000 | U24: 2000000 | V24: 2000000 | W24: 2000000 | X24: 2000000 | Y24: 2000000 | Z24: 2000000
A25: Liability | B25: Net Written Premium | C25: All | D25: UW Year | E25: USD | F25: =EDATE(F24,12) -> 37257 | G25: 1000000 | H25: 2000000 | I25: 2000000 | J25: 2000000 | K25: 2000000 | L25: 2000000 | M25: 2000000 | N25: 2000000 | O25: 2000000 | P25: 2000000 | Q25: 2000000 | R25: 2000000 | S25: 2000000 | T25: 2000000 | U25: 2000000 | V25: 2000000 | W25: 2000000 | X25: 2000000 | Y25: 2000000
A26: Liability | B26: Net Written Premium | C26: All | D26: UW Year | E26: USD | F26: =EDATE(F25,12) -> 37622 | G26: 1000000 | H26: 2000000 | I26: 2000000 | J26: 2000000 | K26: 2000000 | L26: 2000000 | M26: 2000000 | N26: 2000000 | O26: 2000000 | P26: 2000000 | Q26: 2000000 | R26: 2000000 | S26: 2000000 | T26: 2000000 | U26: 2000000 | V26: 2000000 | W26: 2000000 | X26: 2000000
A27: Liability | B27: Net Written Premium | C27: All | D27: UW Year | E27: USD | F27: =EDATE(F26,12) -> 37987 | G27: 1000000 | H27: 2000000 | I27: 2000000 | J27: 2000000 | K27: 2000000 | L27: 2000000 | M27: 2000000 | N27: 2000000 | O27: 2000000 | P27: 2000000 | Q27: 2000000 | R27: 2000000 | S27: 2000000 | T27: 2000000 | U27: 2000000 | V27: 2000000 | W27: 2000000
A28: Liability | B28: Net Written Premium | C28: All | D28: UW Year | E28: USD | F28: =EDATE(F27,12) -> 38353 | G28: 1000000 | H28: 2000000 | I28: 2000000 | J28: 2000000 | K28: 2000000 | L28: 2000000 | M28: 2000000 | N28: 2000000 | O28: 2000000 | P28: 2000000 | Q28: 2000000 | R28: 2000000 | S28: 2000000 | T28: 2000000 | U28: 2000000 | V28: 2000000
A29: Liability | B29: Net Written Premium | C29: All | D29: UW Year | E29: USD | F29: =EDATE(F28,12) -> 38718 | G29: 1000000 | H29: 2000000 | I29: 2000000 | J29: 2000000 | K29: 2000000 | L29: 2000000 | M29: 2000000 | N29: 2000000 | O29: 2000000 | P29: 2000000 | Q29: 2000000 | R29: 2000000 | S29: 2000000 | T29: 2000000 | U29: 2000000
A30: Liability | B30: Net Written Premium | C30: All | D30: UW Year | E30: USD | F30: =EDATE(F29,12) -> 39083 | G30: 1000000 | H30: 2000000 | I30: 2000000 | J30: 2000000 | K30: 2000000 | L30: 2000000 | M30: 2000000 | N30: 2000000 | O30: 2000000 | P30: 2000000 | Q30: 2000000 | R30: 2000000 | S30: 2000000 | T30: 2000000
A31: Liability | B31: Net Written Premium | C31: All | D31: UW Year | E31: USD | F31: =EDATE(F30,12) -> 39448 | G31: 1000000 | H31: 2000000 | I31: 2000000 | J31: 2000000 | K31: 2000000 | L31: 2000000 | M31: 2000000 | N31: 2000000 | O31: 2000000 | P31: 2000000 | Q31: 2000000 | R31: 2000000 | S31: 2000000
A32: Liability | B32: Net Written Premium | C32: All | D32: UW Year | E32: USD | F32: =EDATE(F31,12) -> 39814 | G32: 1000000 | H32: 2000000 | I32: 2000000 | J32: 2000000 | K32: 2000000 | L32: 2000000 | M32: 2000000 | N32: 2000000 | O32: 2000000 | P32: 2000000 | Q32: 2000000 | R32: 2000000
A33: Liability | B33: Net Written Premium | C33: All | D33: UW Year | E33: USD | F33: =EDATE(F32,12) -> 40179 | G33: 1000000 | H33: 2000000 | I33: 2000000 | J33: 2000000 | K33: 2000000 | L33: 2000000 | M33: 2000000 | N33: 2000000 | O33: 2000000 | P33: 2000000 | Q33: 2000000
A34: Liability | B34: Net Written Premium | C34: All | D34: UW Year | E34: USD | F34: =EDATE(F33,12) -> 40544 | G34: 1000000 | H34: 2000000 | I34: 2000000 | J34: 2000000 | K34: 2000000 | L34: 2000000 | M34: 2000000 | N34: 2000000 | O34: 2000000 | P34: 2000000
A35: Liability | B35: Net Written Premium | C35: All | D35: UW Year | E35: USD | F35: =EDATE(F34,12) -> 40909 | G35: 1000000 | H35: 2000000 | I35: 2000000 | J35: 2000000 | K35: 2000000 | L35: 2000000 | M35: 2000000 | N35: 2000000 | O35: 2000000
A36: Liability | B36: Net Written Premium | C36: All | D36: UW Year | E36: USD | F36: =EDATE(F35,12) -> 41275 | G36: 1000000 | H36: 2000000 | I36: 2000000 | J36: 2000000 | K36: 2000000 | L36: 2000000 | M36: 2000000 | N36: 2000000
A37: Liability | B37: Net Written Premium | C37: All | D37: UW Year | E37: USD | F37: =EDATE(F36,12) -> 41640 | G37: 1000000 | H37: 2000000 | I37: 2000000 | J37: 2000000 | K37: 2000000 | L37: 2000000 | M37: 2000000
A38: Liability | B38: Net Written Premium | C38: All | D38: UW Year | E38: USD | F38: =EDATE(F37,12) -> 42005 | G38: 1000000 | H38: 2000000 | I38: 2000000 | J38: 2000000 | K38: 2000000 | L38: 2000000
A39: Liability | B39: Net Written Premium | C39: All | D39: UW Year | E39: USD | F39: =EDATE(F38,12) -> 42370 | G39: 1000000 | H39: 2000000 | I39: 2000000 | J39: 2000000 | K39: 2000000
A40: Liability | B40: Net Written Premium | C40: All | D40: UW Year | E40: USD | F40: =EDATE(F39,12) -> 42736 | G40: 1000000 | H40: 2000000 | I40: 2000000 | J40: 2000000
A41: Liability | B41: Net Written Premium | C41: All | D41: UW Year | E41: USD | F41: =EDATE(F40,12) -> 43101 | G41: 1000000 | H41: 2000000 | I41: 2000000
...

Sheet Example - Projections
A1: Longtail Reference | B1: UW Year | C1: Ultimate GG Prem ($M) | D1: Latest GG Prem ($M) | E1: Latest GN Prem ($M) | F1: Acq Cost | G1: Cedant Provided Ultimate Loss Ratio | H1: Cedant Provided CoV | I1: Rate Change | J1: Inflation | K1: Historic Year Check | L1: Current Year Check | M1: Min Origin Year: | N1: =YEAR(triangle_start_date) -> 2001 | O1: Max Origin Year: | P1: =YEAR(current_date)-1 -> 2025 | R1: Checks
A2: ='Example - Parameters'!C219 -> Professional Lines | B2: =YEAR(triangle_start_date) -> 2001 | C2: <in millions> | D2: <in millions> | E2: =IF(D2="", "", IFERROR(D2*(1-F2),"")) | K2: =IF(OR(B2<$N$1,B2>$P$1),"fail","pass") -> pass | L2: =IFERROR(IF(AND(MATCH(A2,Projection_classes,0),YEAR(current_date)='Example - Projections'!B2),"pass","fail"),"") | R2: =IF(S2>0, "RATE CHANGE COLUMN CONTAINS ERROR VALUES. PLEASE SET THEM TO 0s", "Rate Change column no error values.") -> Rate Change column no error values. | S2: {=SUMPRODUCT(--ISERROR(I2:I1000))} -> 0
A3: =A2 -> Professional Lines | B3: =B2+1 -> 2002 | C3: <in millions> | D3: <in millions> | E3: =IF(D3="", "", IFERROR(D3*(1-F3),"")) | K3: =IF(OR(B3<$N$1,B3>$P$1),"fail","pass") -> pass | L3: =IFERROR(IF(AND(MATCH(A3,Projection_classes,0),YEAR(current_date)='Example - Projections'!B3),"pass","fail"),"") | R3: =IF(S3>0, "INFLATION COLUMN CONTAINS ERROR VALUES. PLEASE SET THEM TO 0s", "Inflation column no error values.") -> Inflation column no error values. | S3: {=SUMPRODUCT(--ISERROR(J2:J1000))} -> 0
A4: =A3 -> Professional Lines | B4: =B3+1 -> 2003 | C4: <in millions> | D4: <in millions> | E4: =IF(D4="", "", IFERROR(D4*(1-F4),"")) | K4: =IF(OR(B4<$N$1,B4>$P$1),"fail","pass") -> pass | L4: =IFERROR(IF(AND(MATCH(A4,Projection_classes,0),YEAR(current_date)='Example - Projections'!B4),"pass","fail"),"")
A5: =A4 -> Professional Lines | B5: =B4+1 -> 2004 | C5: <in millions> | D5: <in millions> | E5: =IF(D5="", "", IFERROR(D5*(1-F5),"")) | K5: =IF(OR(B5<$N$1,B5>$P$1),"fail","pass") -> pass | L5: =IFERROR(IF(AND(MATCH(A5,Projection_classes,0),YEAR(current_date)='Example - Projections'!B5),"pass","fail"),"")
A6: =A5 -> Professional Lines | B6: =B5+1 -> 2005 | C6: <in millions> | D6: <in millions> | E6: =IF(D6="", "", IFERROR(D6*(1-F6),"")) | K6: =IF(OR(B6<$N$1,B6>$P$1),"fail","pass") -> pass | L6: =IFERROR(IF(AND(MATCH(A6,Projection_classes,0),YEAR(current_date)='Example - Projections'!B6),"pass","fail"),"") | R6: Mandatory
A7: =A6 -> Professional Lines | B7: =B6+1 -> 2006 | E7: <drag down above formula> | K7: =IF(OR(B7<$N$1,B7>$P$1),"fail","pass") -> pass | L7: =IFERROR(IF(AND(MATCH(A7,Projection_classes,0),YEAR(current_date)='Example - Projections'!B7),"pass","fail"),"") | R7: Optional
A8: =A7 -> Professional Lines | B8: =B7+1 -> 2007 | E8: <drag down above formula> | K8: =IF(OR(B8<$N$1,B8>$P$1),"fail","pass") -> pass | L8: =IFERROR(IF(AND(MATCH(A8,Projection_classes,0),YEAR(current_date)='Example - Projections'!B8),"pass","fail"),"")
A9: =A8 -> Professional Lines | B9: =B8+1 -> 2008 | E9: <drag down above formula> | K9: =IF(OR(B9<$N$1,B9>$P$1),"fail","pass") -> pass | L9: =IFERROR(IF(AND(MATCH(A9,Projection_classes,0),YEAR(current_date)='Example - Projections'!B9),"pass","fail"),"")
A10: =A9 -> Professional Lines | B10: =B9+1 -> 2009 | E10: <drag down above formula> | K10: =IF(OR(B10<$N$1,B10>$P$1),"fail","pass") -> pass | L10: =IFERROR(IF(AND(MATCH(A10,Projection_classes,0),YEAR(current_date)='Example - Projections'!B10),"pass","fail"),"")
A11: =A10 -> Professional Lines | B11: =B10+1 -> 2010 | E11: <drag down above formula> | K11: =IF(OR(B11<$N$1,B11>$P$1),"fail","pass") -> pass | L11: =IFERROR(IF(AND(MATCH(A11,Projection_classes,0),YEAR(current_date)='Example - Projections'!B11),"pass","fail"),"")
A12: =A11 -> Professional Lines | B12: =B11+1 -> 2011 | K12: =IF(OR(B12<$N$1,B12>$P$1),"fail","pass") -> pass | L12: =IFERROR(IF(AND(MATCH(A12,Projection_classes,0),YEAR(current_date)='Example - Projections'!B12),"pass","fail"),"")
A13: =A12 -> Professional Lines | B13: =B12+1 -> 2012 | K13: =IF(OR(B13<$N$1,B13>$P$1),"fail","pass") -> pass | L13: =IFERROR(IF(AND(MATCH(A13,Projection_classes,0),YEAR(current_date)='Example - Projections'!B13),"pass","fail"),"")
A14: =A13 -> Professional Lines | B14: =B13+1 -> 2013 | K14: =IF(OR(B14<$N$1,B14>$P$1),"fail","pass") -> pass | L14: =IFERROR(IF(AND(MATCH(A14,Projection_classes,0),YEAR(current_date)='Example - Projections'!B14),"pass","fail"),"")
A15: =A14 -> Professional Lines | B15: =B14+1 -> 2014 | K15: =IF(OR(B15<$N$1,B15>$P$1),"fail","pass") -> pass | L15: =IFERROR(IF(AND(MATCH(A15,Projection_classes,0),YEAR(current_date)='Example - Projections'!B15),"pass","fail"),"")
A16: =A15 -> Professional Lines | B16: =B15+1 -> 2015 | K16: =IF(OR(B16<$N$1,B16>$P$1),"fail","pass") -> pass | L16: =IFERROR(IF(AND(MATCH(A16,Projection_classes,0),YEAR(current_date)='Example - Projections'!B16),"pass","fail"),"")
A17: =A16 -> Professional Lines | B17: =B16+1 -> 2016 | K17: =IF(OR(B17<$N$1,B17>$P$1),"fail","pass") -> pass | L17: =IFERROR(IF(AND(MATCH(A17,Projection_classes,0),YEAR(current_date)='Example - Projections'!B17),"pass","fail"),"")
A18: =A17 -> Professional Lines | B18: =B17+1 -> 2017 | K18: =IF(OR(B18<$N$1,B18>$P$1),"fail","pass") -> pass | L18: =IFERROR(IF(AND(MATCH(A18,Projection_classes,0),YEAR(current_date)='Example - Projections'!B18),"pass","fail"),"")
A19: =A18 -> Professional Lines | B19: =B18+1 -> 2018 | K19: =IF(OR(B19<$N$1,B19>$P$1),"fail","pass") -> pass | L19: =IFERROR(IF(AND(MATCH(A19,Projection_classes,0),YEAR(current_date)='Example - Projections'!B19),"pass","fail"),"")
A20: =A19 -> Professional Lines | B20: =B19+1 -> 2019 | K20: =IF(OR(B20<$N$1,B20>$P$1),"fail","pass") -> pass | L20: =IFERROR(IF(AND(MATCH(A20,Projection_classes,0),YEAR(current_date)='Example - Projections'!B20),"pass","fail"),"")
A21: =A20 -> Professional Lines | B21: =B20+1 -> 2020 | K21: =IF(OR(B21<$N$1,B21>$P$1),"fail","pass") -> pass | L21: =IFERROR(IF(AND(MATCH(A21,Projection_classes,0),YEAR(current_date)='Example - Projections'!B21),"pass","fail"),"")
A22: ='Example - Parameters'!C220 -> Liability | B22: =YEAR(triangle_start_date) -> 2001 | K22: =IF(OR(B22<$N$1,B22>$P$1),"fail","pass") -> pass | L22: =IFERROR(IF(AND(MATCH(A22,Projection_classes,0),YEAR(current_date)='Example - Projections'!B22),"pass","fail"),"")
A23: =A22 -> Liability | B23: =B22+1 -> 2002 | K23: =IF(OR(B23<$N$1,B23>$P$1),"fail","pass") -> pass | L23: =IFERROR(IF(AND(MATCH(A23,Projection_classes,0),YEAR(current_date)='Example - Projections'!B23),"pass","fail"),"")
A24: =A23 -> Liability | B24: =B23+1 -> 2003 | K24: =IF(OR(B24<$N$1,B24>$P$1),"fail","pass") -> pass | L24: =IFERROR(IF(AND(MATCH(A24,Projection_classes,0),YEAR(current_date)='Example - Projections'!B24),"pass","fail"),"")
A25: =A24 -> Liability | B25: =B24+1 -> 2004 | K25: =IF(OR(B25<$N$1,B25>$P$1),"fail","pass") -> pass | L25: =IFERROR(IF(AND(MATCH(A25,Projection_classes,0),YEAR(current_date)='Example - Projections'!B25),"pass","fail"),"")
A26: =A25 -> Liability | B26: =B25+1 -> 2005 | K26: =IF(OR(B26<$N$1,B26>$P$1),"fail","pass") -> pass | L26: =IFERROR(IF(AND(MATCH(A26,Projection_classes,0),YEAR(current_date)='Example - Projections'!B26),"pass","fail"),"")
A27: =A26 -> Liability | B27: =B26+1 -> 2006 | K27: =IF(OR(B27<$N$1,B27>$P$1),"fail","pass") -> pass | L27: =IFERROR(IF(AND(MATCH(A27,Projection_classes,0),YEAR(current_date)='Example - Projections'!B27),"pass","fail"),"")
A28: =A27 -> Liability | B28: =B27+1 -> 2007 | K28: =IF(OR(B28<$N$1,B28>$P$1),"fail","pass") -> pass | L28: =IFERROR(IF(AND(MATCH(A28,Projection_classes,0),YEAR(current_date)='Example - Projections'!B28),"pass","fail"),"")
A29: =A28 -> Liability | B29: =B28+1 -> 2008 | K29: =IF(OR(B29<$N$1,B29>$P$1),"fail","pass") -> pass | L29: =IFERROR(IF(AND(MATCH(A29,Projection_classes,0),YEAR(current_date)='Example - Projections'!B29),"pass","fail"),"")
A30: =A29 -> Liability | B30: =B29+1 -> 2009 | K30: =IF(OR(B30<$N$1,B30>$P$1),"fail","pass") -> pass | L30: =IFERROR(IF(AND(MATCH(A30,Projection_classes,0),YEAR(current_date)='Example - Projections'!B30),"pass","fail"),"")
A31: =A30 -> Liability | B31: =B30+1 -> 2010 | K31: =IF(OR(B31<$N$1,B31>$P$1),"fail","pass") -> pass | L31: =IFERROR(IF(AND(MATCH(A31,Projection_classes,0),YEAR(current_date)='Example - Projections'!B31),"pass","fail"),"")
A32: =A31 -> Liability | B32: =B31+1 -> 2011 | K32: =IF(OR(B32<$N$1,B32>$P$1),"fail","pass") -> pass | L32: =IFERROR(IF(AND(MATCH(A32,Projection_classes,0),YEAR(current_date)='Example - Projections'!B32),"pass","fail"),"")
A33: =A32 -> Liability | B33: =B32+1 -> 2012 | K33: =IF(OR(B33<$N$1,B33>$P$1),"fail","pass") -> pass | L33: =IFERROR(IF(AND(MATCH(A33,Projection_classes,0),YEAR(current_date)='Example - Projections'!B33),"pass","fail"),"")
A34: =A33 -> Liability | B34: =B33+1 -> 2013 | K34: =IF(OR(B34<$N$1,B34>$P$1),"fail","pass") -> pass | L34: =IFERROR(IF(AND(MATCH(A34,Projection_classes,0),YEAR(current_date)='Example - Projections'!B34),"pass","fail"),"")
