Workbook
Name Country_list: Lookups!$H$3:$H$252
Name Currency_list: Lookups!$P$3:$P$163
Name current_date: 'Example - Parameters'!$D$9
Name current_date: Parameters!$D$9
Name Development_classes: 'Example - Parameters'!$C$14:$C$213
Name Development_classes: Parameters!$C$14:$C$213
Name IQ_CH: 110000
Name IQ_CQ: 5000
Name IQ_CY: 10000
Name IQ_DAILY: 500000
Name IQ_FH: 100000
Name IQ_FQ: 500
Name IQ_FY: 1000
Name IQ_LTM: 2000
Name IQ_MONTH: 15000
Name IQ_NTM: 6000
Name IQ_WEEK: 50000
Name IQ_YTD: 3000
Name LDF_type_options: Lookups!$R$3:$R$6
Name LOBs_names: Lookups!$B$3:$B$25
Name month_final_development: 'Example - Parameters'!$D$8
Name month_final_development: Parameters!$D$8
Name month_first_development: 'Example - Parameters'!$D$5
Name month_first_development: Parameters!$D$5
Name P_NP_types: Lookups!$E$3:$E$6
Name Projection_classes: 'Example - Parameters'!$C$219:$C$418
Name Projection_classes: Parameters!$C$219:$C$418
Name re_insurance_list: Lookups!$N$3:$N$5
Name Region_list: Lookups!$K$3:$K$8
Name triangle_grouping_data: 'Example - Parameters'!$C$219:$AA$418
Name triangle_grouping_data: Parameters!$C$219:$AA$418
Name triangle_increments_months: 'Example - Parameters'!$D$6
Name triangle_increments_months: Parameters!$D$6
Name triangle_start_date: 'Example - Parameters'!$D$4
Name triangle_start_date: Parameters!$D$4

Sheet Parameters
B3: Triangle Shape Parameters | E3: guide | F3: Checks
C4: Triangle start (t=0) date | D4: 38718 | E4: YYYY-MM-DD | F4: =triangle_start_date=Triangles!F3 -> TRUE | H4: Mandatory
C5: Month of first development | D5: 9 | E5: first month in triangle | H5: Optional
C6: Development period increments (months) | D6: 12 | E6: triangle increments (column)
C7: Origin period increments (months) | D7: 12 | E7: triangle increments (row)
C8: Month of final development | D8: 237 | E8: Latest month in the largest triangle | F8: =IF(ISERROR(MATCH(month_final_development,Triangles!$G$2:$FA$2, 0)), "Can't find this development month in triangle. Please be consistent with Triangle.", "OK") -> OK
C9: Inception Date | D9: 46023 | E9: YYYY-MM-DD
C10: Expiry Date | D10: 46387 | E10: YYYY-MM-DD
B11: Triangular data list (LOB/Class)
Q12: Cedant Business Segment Names (Optional)
B13: # | C13: Triangle Name | D13: Proportional/Non-proportional | E13: Region | F13: Country | G13: Re/Ins/Retro | H13: LT LOB 1 (Dropdown List) | I13: LT LOB 1 Allocation | J13: LT LOB 2 (Dropdown List) | K13: LT LOB 2 Allocation | L13: LT LOB 3 (Dropdown List) | M13: LT LOB 3 Allocation | N13: LT LOB 4 (Dropdown List) | O13: LT LOB 4 Allocation | P13: LT LOB 5 (Dropdown List) | Q13: LT LOB 5 Allocation | R13: Allocation Check | S13: Currency | T13: Currency Rate | U13: Segment 1 | V13: Segment 2 | W13: Segment 3 | X13: Segment 4 | Y13: Segment 5 | Z13: Premium Triangle Source | AA13: Incurred Triangle Source | AB13: Paid Triangle Source | AC13: Ultimate Triangle Source
B14: 1 | C14: =[1]INDEX!C31 -> Professional Lines | D14: Mixed | E14: Worldwide | F14: Multi-country | G14: Retrocession | H14: Professional Liability | I14: 1 | R14: =IF(AND(C14<>"",SUM(I14,K14,M14,O14,Q14)=1),"pass",IF(AND(C14="",SUM(I14,K14,M14,O14,Q14)=0),"pass","fail")) -> pass | Z14: Cedant provided | AA14: Cedant provided | AB14: Cedant provided
B15: 2 | C15: =[1]INDEX!C32 -> Liability | D15: Mixed | E15: Worldwide | F15: Multi-country | G15: Retrocession | H15: Casualty | I15: 1 | R15: =IF(AND(C15<>"",SUM(I15,K15,M15,O15,Q15)=1),"pass",IF(AND(C15="",SUM(I15,K15,M15,O15,Q15)=0),"pass","fail")) -> pass | Z15: Cedant provided | AA15: Cedant provided | AB15: Cedant provided
B16: 3 | C16: =[1]INDEX!C33 -> Credit & Surety | D16: Mixed | E16: Worldwide | F16: Multi-country | G16: Retrocession | H16: Fidelity & Surety | I16: 1 | R16: =IF(AND(C16<>"",SUM(I16,K16,M16,O16,Q16)=1),"pass",IF(AND(C16="",SUM(I16,K16,M16,O16,Q16)=0),"pass","fail")) -> pass | Z16: Cedant provided | AA16: Cedant provided | AB16: Cedant provided
B17: 4 | C17: =[1]INDEX!C34 -> Motor NP | D17: Non Proportional | E17: Worldwide ex US | F17: Multi-country | G17: Retrocession | H17: Motor | I17: 1 | R17: =IF(AND(C17<>"",SUM(I17,K17,M17,O17,Q17)=1),"pass",IF(AND(C17="",SUM(I17,K17,M17,O17,Q17)=0),"pass","fail")) -> pass | Z17: Cedant provided | AA17: Cedant provided | AB17: Cedant provided
B18: 5 | C18: =[1]INDEX!C35 -> Motor PR | D18: Proportional | E18: Worldwide ex US | F18: Multi-country | G18: Retrocession | H18: Motor | I18: 1 | R18: =IF(AND(C18<>"",SUM(I18,K18,M18,O18,Q18)=1),"pass",IF(AND(C18="",SUM(I18,K18,M18,O18,Q18)=0),"pass","fail")) -> pass | Z18: Cedant provided | AA18: Cedant provided | AB18: Cedant provided
B19: 6 | C19: =[1]INDEX!C36 -> Cyber | D19: Mixed | E19: Worldwide | F19: Multi-country | G19: Retrocession | H19: Cyber | I19: 1 | R19: =IF(AND(C19<>"",SUM(I19,K19,M19,O19,Q19)=1),"pass",IF(AND(C19="",SUM(I19,K19,M19,O19,Q19)=0),"pass","fail")) -> pass | Z19: Cedant provided | AA19: Cedant provided | AB19: Cedant provided
B20: 7 | R20: =IF(AND(C20<>"",SUM(I20,K20,M20,O20,Q20)=1),"pass",IF(AND(C20="",SUM(I20,K20,M20,O20,Q20)=0),"pass","fail")) -> pass
B21: 8 | R21: =IF(AND(C21<>"",SUM(I21,K21,M21,O21,Q21)=1),"pass",IF(AND(C21="",SUM(I21,K21,M21,O21,Q21)=0),"pass","fail")) -> pass
B22: 9 | R22: =IF(AND(C22<>"",SUM(I22,K22,M22,O22,Q22)=1),"pass",IF(AND(C22="",SUM(I22,K22,M22,O22,Q22)=0),"pass","fail")) -> pass
B23: 10 | R23: =IF(AND(C23<>"",SUM(I23,K23,M23,O23,Q23)=1),"pass",IF(AND(C23="",SUM(I23,K23,M23,O23,Q23)=0),"pass","fail")) -> pass
B24: 11 | R24: =IF(AND(C24<>"",SUM(I24,K24,M24,O24,Q24)=1),"pass",IF(AND(C24="",SUM(I24,K24,M24,O24,Q24)=0),"pass","fail")) -> pass
B25: 12 | R25: =IF(AND(C25<>"",SUM(I25,K25,M25,O25,Q25)=1),"pass",IF(AND(C25="",SUM(I25,K25,M25,O25,Q25)=0),"pass","fail")) -> pass
B26: 13 | R26: =IF(AND(C26<>"",SUM(I26,K26,M26,O26,Q26)=1),"pass",IF(AND(C26="",SUM(I26,K26,M26,O26,Q26)=0),"pass","fail")) -> pass
B27: 14 | R27: =IF(AND(C27<>"",SUM(I27,K27,M27,O27,Q27)=1),"pass",IF(AND(C27="",SUM(I27,K27,M27,O27,Q27)=0),"pass","fail")) -> pass
B28: 15 | R28: =IF(AND(C28<>"",SUM(I28,K28,M28,O28,Q28)=1),"pass",IF(AND(C28="",SUM(I28,K28,M28,O28,Q28)=0),"pass","fail")) -> pass
B29: 16 | R29: =IF(AND(C29<>"",SUM(I29,K29,M29,O29,Q29)=1),"pass",IF(AND(C29="",SUM(I29,K29,M29,O29,Q29)=0),"pass","fail")) -> pass
B30: 17 | R30: =IF(AND(C30<>"",SUM(I30,K30,M30,O30,Q30)=1),"pass",IF(AND(C30="",SUM(I30,K30,M30,O30,Q30)=0),"pass","fail")) -> pass
B31: 18 | R31: =IF(AND(C31<>"",SUM(I31,K31,M31,O31,Q31)=1),"pass",IF(AND(C31="",SUM(I31,K31,M31,O31,Q31)=0),"pass","fail")) -> pass
... B37: 24 | R37: =IF(AND(C37<>"",SUM(I37,K37,M37,O37,Q37)=1),"pass",IF(AND(C37="",SUM(I37,K37,M37,O37,Q37)=0),"pass","fail")) -> pass
B38: 25
B39: 26
B40: 27
B41: 28
B42: 29
B43: 30
B44: 31
B45: 32
B46: 33
B47: 34
...

Sheet Triangles
G1: Development months
A2: LOB (dropdown) | B2: Type (Incurred / Paid …) | C2: Loss type | D2: Basis (Accident Year / UW Year) | E2: Currency (e.g. USD, GBP …) | F2: Origin Year | G2: =month_first_development -> 9 | H2: =G2+triangle_increments_months -> 21 | I2: =H2+triangle_increments_months -> 33 | J2: =I2+triangle_increments_months -> 45 | K2: =J2+triangle_increments_months -> 57 | L2: =K2+triangle_increments_months -> 69 | M2: =L2+triangle_increments_months -> 81 | N2: =M2+triangle_increments_months -> 93 | O2: =N2+triangle_increments_months -> 105 | ... FA2: =EZ2+triangle_increments_months -> 1809
A3: Professional Lines | B3: Net Written Premium | C3: All | D3: UW Year | E3: USD | F3: =triangle_start_date -> 38718 | G3: {=IF(EDATE($F3,G$2)>DATE(2025,12,31),"",INDEX([1]A1!D$9:D$175,MATCH(1,--(RIGHT([1]A1!$B$9:$B$175,LEN([1]A1!$B$9:$B$175)-4)=$A3)*([1]A1!$C$9:$C$175=YEAR($F3)),0)))} -> 82791142 | H3: {=IF(EDATE($F3,H$2)>DATE(2025,12,31),"",INDEX([1]A1!E$9:E$175,MATCH(1,--(RIGHT([1]A1!$B$9:$B$175,LEN([1]A1!$B$9:$B$175)-4)=$A3)*([1]A1!$C$9:$C$175=YEAR($F3)),0)))} -> 2.2278574e+08 | I3: {=IF(EDATE($F3,I$2)>DATE(2025,12,31),"",INDEX([1]A1!F$9:F$175,MATCH(1,--(RIGHT([1]A1!$B$9:$B$175,LEN([1]A1!$B$9:$B$175)-4)=$A3)*([1]A1!$C$9:$C$175=YEAR($F3)),0)))} -> 2.4786954e+08 | J3: {=IF(EDATE($F3,J$2)>DATE(2025,12,31),"",INDEX([1]A1!G$9:G$175,MATCH(1,--(RIGHT([1]A1!$B$9:$B$175,LEN([1]A1!$B$9:$B$175)-4)=$A3)*([1]A1!$C$9:$C$175=YEAR($F3)),0)))} -> 2.5024867e+08 | K3: {=IF(EDATE($F3,K$2)>DATE(2025,12,31),"",INDEX([1]A1!H$9:H$175,MATCH(1,--(RIGHT([1]A1!$B$9:$B$175,LEN([1]A1!$B$9:$B$175)-4)=$A3)*([1]A1!$C$9:$C$175=YEAR($F3)),0)))} -> 2.470133e+08 | L3: {=IF(EDATE($F3,L$2)>DATE(2025,12,31),"",INDEX([1]A1!I$9:I$175,MATCH(1,--(RIGHT([1]A1!$B$9:$B$175,LEN([1]A1!$B$9:$B$175)-4)=$A3)*([1]A1!$C$9:$C$175=YEAR($F3)),0)))} -> 2.454515e+08 | M3: {=IF(EDATE($F3,M$2)>DATE(2025,12,31),"",INDEX([1]A1!J$9:J$175,MATCH(1,--(RIGHT([1]A1!$B$9:$B$175,LEN([1]A1!$B$9:$B$175)-4)=$A3)*([1]A1!$C$9:$C$175=YEAR($F3)),0)))} -> 2.4630898e+08 | N3: {=IF(EDATE($F3,N$2)>DATE(2025,12,31),"",INDEX([1]A1!K$9:K$175,MATCH(1,--(RIGHT([1]A1!$B$9:$B$175,LEN([1]A1!$B$9:$B$175)-4)=$A3)*([1]A1!$C$9:$C$175=YEAR($F3)),0)))} -> 2.4796129e+08 | ... FA3: {=IF(EDATE($F3,FA$2)>DATE(2025,12,31),"",INDEX([1]A1!EX$9:EX$175,MATCH(1,--(RIGHT([1]A1!$B$9:$B$175,LEN([1]A1!$B$9:$B$175)-4)=$A3)*([1]A1!$C$9:$C$175=YEAR($F3)),0)))}
A4: Professional Lines | B4: Net Written Premium | C4: All | D4: UW Year | E4: USD | F4: =EDATE(F3,12) -> 39083 | G4: {=IF(EDATE($F4,G$2)>DATE(2025,12,31),"",INDEX([1]A1!D$9:D$175,MATCH(1,--(RIGHT([1]A1!$B$9:$B$175,LEN([1]A1!$B$9:$B$175)-4)=$A4)*([1]A1!$C$9:$C$175=YEAR($F4)),0)))} -> 82434469 | H4: {=IF(EDATE($F4,H$2)>DATE(2025,12,31),"",INDEX([1]A1!E$9:E$175,MATCH(1,--(RIGHT([1]A1!$B$9:$B$175,LEN([1]A1!$B$9:$B$175)-4)=$A4)*([1]A1!$C$9:$C$175=YEAR($F4)),0)))} -> 1.7501938e+08 | I4: {=IF(EDATE($F4,I$2)>DATE(2025,12,31),"",INDEX([1]A1!F$9:F$175,MATCH(1,--(RIGHT([1]A1!$B$9:$B$175,LEN([1]A1!$B$9:$B$175)-4)=$A4)*([1]A1!$C$9:$C$175=YEAR($F4)),0)))} -> 2.0186393e+08 | J4: {=IF(EDATE($F4,J$2)>DATE(2025,12,31),"",INDEX([1]A1!G$9:G$175,MATCH(1,--(RIGHT([1]A1!$B$9:$B$175,LEN([1]A1!$B$9:$B$175)-4)=$A4)*([1]A1!$C$9:$C$175=YEAR($F4)),0)))} -> 2.0477241e+08 | K4: {=IF(EDATE($F4,K$2)>DATE(2025,12,31),"",INDEX([1]A1!H$9:H$175,MATCH(1,--(RIGHT([1]A1!$B$9:$B$175,LEN([1]A1!$B$9:$B$175)-4)=$A4)*([1]A1!$C$9:$C$175=YEAR($F4)),0)))} -> 2.0526614e+08 | L4: {=IF(EDATE($F4,L$2)>DATE(2025,12,31),"",INDEX([1]A1!I$9:I$175,MATCH(1,--(RIGHT([1]A1!$B$9:$B$175,LEN([1]A1!$B$9:$B$175)-4)=$A4)*([1]A1!$C$9:$C$175=YEAR($F4)),0)))} -> 2.0522873e+08 | M4: {=IF(EDATE($F4,M$2)>DATE(2025,12,31),"",INDEX([1]A1!J$9:J$175,MATCH(1,--(RIGHT([1]A1!$B$9:$B$175,LEN([1]A1!$B$9:$B$175)-4)=$A4)*([1]A1!$C$9:$C$175=YEAR($F4)),0)))} -> 2.0931202e+08 | N4: {=IF(EDATE($F4,N$2)>DATE(2025,12,31),"",INDEX([1]A1!K$9:K$175,MATCH(1,--(RIGHT([1]A1!$B$9:$B$175,LEN([1]A1!$B$9:$B$175)-4)=$A4)*([1]A1!$C$9:$C$175=YEAR($F4)),0)))} -> 2.087931e+08 | ... FA4: {=IF(EDATE($F4,FA$2)>DATE(2025,12,31),"",INDEX([1]A1!EX$9:EX$175,MATCH(1,--(RIGHT([1]A1!$B$9:$B$175,LEN([1]A1!$B$9:$B$175)-4)=$A4)*([1]A1!$C$9:$C$175=YEAR($F4)),0)))}
A5: Professional Lines | B5: Net Written Premium | C5: All | D5: UW Year | E5: USD | F5: =EDATE(F4,12) -> 39448 | G5: {=IF(EDATE($F5,G$2)>DATE(2025,12,31),"",INDEX([1]A1!D$9:D$175,MATCH(1,--(RIGHT([1]A1!$B$9:$B$175,LEN([1]A1!$B$9:$B$175)-4)=$A5)*([1]A1!$C$9:$C$175=YEAR($F5)),0)))} -> 83119039 | H5: {=IF(EDATE($F5,H$2)>DATE(2025,12,31),"",INDEX([1]A1!E$9:E$175,MATCH(1,--(RIGHT([1]A1!$B$9:$B$175,LEN([1]A1!$B$9:$B$175)-4)=$A5)*([1]A1!$C$9:$C$175=YEAR($F5)),0)))} -> 2.2247764e+08 | I5: {=IF(EDATE($F5,I$2)>DATE(2025,12,31),"",INDEX([1]A1!F$9:F$175,MATCH(1,--(RIGHT([1]A1!$B$9:$B$175,LEN([1]A1!$B$9:$B$175)-4)=$A5)*([1]A1!$C$9:$C$175=YEAR($F5)),0)))} -> 2.5904988e+08 | J5: {=IF(EDATE($F5,J$2)>DATE(2025,12,31),"",INDEX([1]A1!G$9:G$175,MATCH(1,--(RIGHT([1]A1!$B$9:$B$175,LEN([1]A1!$B$9:$B$175)-4)=$A5)*([1]A1!$C$9:$C$175=YEAR($F5)),0)))} -> 2.6019818e+08 | K5: {=IF(EDATE($F5,K$2)>DATE(2025,12,31),"",INDEX([1]A1!H$9:H$175,MATCH(1,--(RIGHT([1]A1!$B$9:$B$175,LEN([1]A1!$B$9:$B$175)-4)=$A5)*([1]A1!$C$9:$C$175=YEAR($F5)),0)))} -> 2.6086502e+08 | L5: {=IF(EDATE($F5,L$2)>DATE(2025,12,31),"",INDEX([1]A1!I$9:I$175,MATCH(1,--(RIGHT([1]A1!$B$9:$B$175,LEN([1]A1!$B$9:$B$175)-4)=$A5)*([1]A1!$C$9:$C$175=YEAR($F5)),0)))} -> 2.6381638e+08 | M5: {=IF(EDATE($F5,M$2)>DATE(2025,12,31),"",INDEX([1]A1!J$9:J$175,MATCH(1,--(RIGHT([1]A1!$B$9:$B$175,LEN([1]A1!$B$9:$B$175)-4)=$A5)*([1]A1!$C$9:$C$175=YEAR($F5)),0)))} -> 2.6232004e+08 | N5: {=IF(EDATE($F5,N$2)>DATE(2025,12,31),"",INDEX([1]A1!K$9:K$175,MATCH(1,--(RIGHT([1]A1!$B$9:$B$175,LEN([1]A1!$B$9:$B$175)-4)=$A5)*([1]A1!$C$9:$C$175=YEAR($F5)),0)))} -> 2.6294334e+08 | ... FA5: {=IF(EDATE($F5,FA$2)>DATE(2025,12,31),"",INDEX([1]A1!EX$9:EX$175,MATCH(1,--(RIGHT([1]A1!$B$9:$B$175,LEN([1]A1!$B$9:$B$175)-4)=$A5)*([1]A1!$C$9:$C$175=YEAR($F5)),0)))}
A6: Professional Lines | B6: Net Written Premium | C6: All | D6: UW Year | E6: USD | F6: =EDATE(F5,12) -> 39814 | G6: {=IF(EDATE($F6,G$2)>DATE(2025,12,31),"",INDEX([1]A1!D$9:D$175,MATCH(1,--(RIGHT([1]A1!$B$9:$B$175,LEN([1]A1!$B$9:$B$175)-4)=$A6)*([1]A1!$C$9:$C$175=YEAR($F6)),0)))} -> 89116218 | H6: {=IF(EDATE($F6,H$2)>DATE(2025,12,31),"",INDEX([1]A1!E$9:E$175,MATCH(1,--(RIGHT([1]A1!$B$9:$B$175,LEN([1]A1!$B$9:$B$175)-4)=$A6)*([1]A1!$C$9:$C$175=YEAR($F6)),0)))} -> 2.5141306e+08 | I6: {=IF(EDATE($F6,I$2)>DATE(2025,12,31),"",INDEX([1]A1!F$9:F$175,MATCH(1,--(RIGHT([1]A1!$B$9:$B$175,LEN([1]A1!$B$9:$B$175)-4)=$A6)*([1]A1!$C$9:$C$175=YEAR($F6)),0)))} -> 2.9932596e+08 | J6: {=IF(EDATE($F6,J$2)>DATE(2025,12,31),"",INDEX([1]A1!G$9:G$175,MATCH(1,--(RIGHT([1]A1!$B$9:$B$175,LEN([1]A1!$B$9:$B$175)-4)=$A6)*([1]A1!$C$9:$C$175=YEAR($F6)),0)))} -> 3.0042299e+08 | K6: {=IF(EDATE($F6,K$2)>DATE(2025,12,31),"",INDEX([1]A1!H$9:H$175,MATCH(1,--(RIGHT([1]A1!$B$9:$B$175,LEN([1]A1!$B$9:$B$175)-4)=$A6)*([1]A1!$C$9:$C$175=YEAR($F6)),0)))} -> 3.0313412e+08 | L6: {=IF(EDATE($F6,L$2)>DATE(2025,12,31),"",INDEX([1]A1!I$9:I$175,MATCH(1,--(RIGHT([1]A1!$B$9:$B$175,LEN([1]A1!$B$9:$B$175)-4)=$A6)*([1]A1!$C$9:$C$175=YEAR($F6)),0)))} -> 3.0246351e+08 | M6: {=IF(EDATE($F6,M$2)>DATE(2025,12,31),"",INDEX([1]A1!J$9:J$175,MATCH(1,--(RIGHT([1]A1!$B$9:$B$175,LEN([1]A1!$B$9:$B$175)-4)=$A6)*([1]A1!$C$9:$C$175=YEAR($F6)),0)))} -> 3.0203602e+08 | N6: {=IF(EDATE($F6,N$2)>DATE(2025,12,31),"",INDEX([1]A1!K$9:K$175,MATCH(1,--(RIGHT([1]A1!$B$9:$B$175,LEN([1]A1!$B$9:$B$175)-4)=$A6)*([1]A1!$C$9:$C$175=YEAR($F6)),0)))} -> 3.0151872e+08 | ... FA6: {=IF(EDATE($F6,FA$2)>DATE(2025,12,31),"",INDEX([1]A1!EX$9:EX$175,MATCH(1,--(RIGHT([1]A1!$B$9:$B$175,LEN([1]A1!$B$9:$B$175)-4)=$A6)*([1]A1!$C$9:$C$175=YEAR($F6)),0)))}
A7: Professional Lines | B7: Net Written Premium | C7: All | D7: UW Year | E7: USD | F7: =EDATE(F6,12) -> 40179 | G7: {=IF(EDATE($F7,G$2)>DATE(2025,12,31),"",INDEX([1]A1!D$9:D$175,MATCH(1,--(RIGHT([1]A1!$B$9:$B$175,LEN([1]A1!$B$9:$B$175)-4)=$A7)*([1]A1!$C$9:$C$175=YEAR($F7)),0)))} -> 83916592 | H7: {=IF(EDATE($F7,H$2)>DATE(2025,12,31),"",INDEX([1]A1!E$9:E$175,MATCH(1,--(RIGHT([1]A1!$B$9:$B$175,LEN([1]A1!$B$9:$B$175)-4)=$A7)*([1]A1!$C$9:$C$175=YEAR($F7)),0)))} -> 2.4892461e+08 | I7: {=IF(EDATE($F7,I$2)>DATE(2025,12,31),"",INDEX([1]A1!F$9:F$175,MATCH(1,--(RIGHT([1]A1!$B$9:$B$175,LEN([1]A1!$B$9:$B$175)-4)=$A7)*([1]A1!$C$9:$C$175=YEAR($F7)),0)))} -> 3.0489379e+08 | J7: {=IF(EDATE($F7,J$2)>DATE(2025,12,31),"",INDEX([1]A1!G$9:G$175,MATCH(1,--(RIGHT([1]A1!$B$9:$B$175,LEN([1]A1!$B$9:$B$175)-4)=$A7)*([1]A1!$C$9:$C$175=YEAR($F7)),0)))} -> 3.0798751e+08 | K7: {=IF(EDATE($F7,K$2)>DATE(2025,12,31),"",INDEX([1]A1!H$9:H$175,MATCH(1,--(RIGHT([1]A1!$B$9:$B$175,LEN([1]A1!$B$9:$B$175)-4)=$A7)*([1]A1!$C$9:$C$175=YEAR($F7)),0)))} -> 3.1182156e+08 | L7: {=IF(EDATE($F7,L$2)>DATE(2025,12,31),"",INDEX([1]A1!I$9:I$175,MATCH(1,--(RIGHT([1]A1!$B$9:$B$175,LEN([1]A1!$B$9:$B$175)-4)=$A7)*([1]A1!$C$9:$C$175=YEAR($F7)),0)))} -> 3.1232055e+08 | M7: {=IF(EDATE($F7,M$2)>DATE(2025,12,31),"",INDEX([1]A1!J$9:J$175,MATCH(1,--(RIGHT([1]A1!$B$9:$B$175,LEN([1]A1!$B$9:$B$175)-4)=$A7)*([1]A1!$C$9:$C$175=YEAR($F7)),0)))} -> 3.1105141e+08 | N7: {=IF(EDATE($F7,N$2)>DATE(2025,12,31),"",INDEX([1]A1!K$9:K$175,MATCH(1,--(RIGHT([1]A1!$B$9:$B$175,LEN([1]A1!$B$9:$B$175)-4)=$A7)*([1]A1!$C$9:$C$175=YEAR($F7)),0)))} -> 3.1073259e+08 | ... FA7: {=IF(EDATE($F7,FA$2)>DATE(2025,12,31),"",INDEX([1]A1!EX$9:EX$175,MATCH(1,--(RIGHT([1]A1!$B$9:$B$175,LEN([1]A1!$B$9:$B$175)-4)=$A7)*([1]A1!$C$9:$C$175=YEAR($F7)),0)))}
A8: Professional Lines | B8: Net Written Premium | C8: All | D8: UW Year | E8: USD | F8: =EDATE(F7,12) -> 40544 | G8: {=IF(EDATE($F8,G$2)>DATE(2025,12,31),"",INDEX([1]A1!D$9:D$175,MATCH(1,--(RIGHT([1]A1!$B$9:$B$175,LEN([1]A1!$B$9:$B$175)-4)=$A8)*([1]A1!$C$9:$C$175=YEAR($F8)),0)))} -> 84620137 | H8: {=IF(EDATE($F8,H$2)>DATE(2025,12,31),"",INDEX([1]A1!E$9:E$175,MATCH(1,--(RIGHT([1]A1!$B$9:$B$175,LEN([1]A1!$B$9:$B$175)-4)=$A8)*([1]A1!$C$9:$C$175=YEAR($F8)),0)))} -> 2.4638227e+08 | I8: {=IF(EDATE($F8,I$2)>DATE(2025,12,31),"",INDEX([1]A1!F$9:F$175,MATCH(1,--(RIGHT([1]A1!$B$9:$B$175,LEN([1]A1!$B$9:$B$175)-4)=$A8)*([1]A1!$C$9:$C$175=YEAR($F8)),0)))} -> 3.0286946e+08 | J8: {=IF(EDATE($F8,J$2)>DATE(2025,12,31),"",INDEX([1]A1!G$9:G$175,MATCH(1,--(RIGHT([1]A1!$B$9:$B$175,LEN([1]A1!$B$9:$B$175)-4)=$A8)*([1]A1!$C$9:$C$175=YEAR($F8)),0)))} -> 3.0591714e+08 | K8: {=IF(EDATE($F8,K$2)>DATE(2025,12,31),"",INDEX([1]A1!H$9:H$175,MATCH(1,--(RIGHT([1]A1!$B$9:$B$175,LEN([1]A1!$B$9:$B$175)-4)=$A8)*([1]A1!$C$9:$C$175=YEAR($F8)),0)))} -> 3.0838051e+08 | L8: {=IF(EDATE($F8,L$2)>DATE(2025,12,31),"",INDEX([1]A1!I$9:I$175,MATCH(1,--(RIGHT([1]A1!$B$9:$B$175,LEN([1]A1!$B$9:$B$175)-4)=$A8)*([1]A1!$C$9:$C$175=YEAR($F8)),0)))} -> 3.0558168e+08 | M8: {=IF(EDATE($F8,M$2)>DATE(2025,12,31),"",INDEX([1]A1!J$9:J$175,MATCH(1,--(RIGHT([1]A1!$B$9:$B$175,LEN([1]A1!$B$9:$B$175)-4)=$A8)*([1]A1!$C$9:$C$175=YEAR($F8)),0)))} -> 3.0591437e+08 | N8: {=IF(EDATE($F8,N$2)>DATE(2025,12,31),"",INDEX([1]A1!K$9:K$175,MATCH(1,--(RIGHT([1]A1!$B$9:$B$175,LEN([1]A1!$B$9:$B$175)-4)=$A8)*([1]A1!$C$9:$C$175=YEAR($F8)),0)))} -> 3.0556627e+08 | ... FA8: {=IF(EDATE($F8,FA$2)>DATE(2025,12,31),"",INDEX([1]A1!EX$9:EX$175,MATCH(1,--(RIGHT([1]A1!$B$9:$B$175,LEN([1]A1!$B$9:$B$175)-4)=$A8)*([1]A1!$C$9:$C$175=YEAR($F8)),0)))}
A9: Professional Lines | B9: Net Written Premium | C9: All | D9: UW Year | E9: USD | F9: =EDATE(F8,12) -> 40909 | G9: {=IF(EDATE($F9,G$2)>DATE(2025,12,31),"",INDEX([1]A1!D$9:D$175,MATCH(1,--(RIGHT([1]A1!$B$9:$B$175,LEN([1]A1!$B$9:$B$175)-4)=$A9)*([1]A1!$C$9:$C$175=YEAR($F9)),0)))} -> 78571029 | H9: {=IF(EDATE($F9,H$2)>DATE(2025,12,31),"",INDEX([1]A1!E$9:E$175,MATCH(1,--(RIGHT([1]A1!$B$9:$B$175,LEN([1]A1!$B$9:$B$175)-4)=$A9)*([1]A1!$C$9:$C$175=YEAR($F9)),0)))} -> 3.0609356e+08 | I9: {=IF(EDATE($F9,I$2)>DATE(2025,12,31),"",INDEX([1]A1!F$9:F$175,MATCH(1,--(RIGHT([1]A1!$B$9:$B$175,LEN([1]A1!$B$9:$B$175)-4)=$A9)*([1]A1!$C$9:$C$175=YEAR($F9)),0)))} -> 3.1354283e+08 | J9: {=IF(EDATE($F9,J$2)>DATE(2025,12,31),"",INDEX([1]A1!G$9:G$175,MATCH(1,--(RIGHT([1]A1!$B$9:$B$175,LEN([1]A1!$B$9:$B$175)-4)=$A9)*([1]A1!$C$9:$C$175=YEAR($F9)),0)))} -> 3.1824168e+08 | K9: {=IF(EDATE($F9,K$2)>DATE(2025,12,31),"",INDEX([1]A1!H$9:H$175,MATCH(1,--(RIGHT([1]A1!$B$9:$B$175,LEN([1]A1!$B$9:$B$175)-4)=$A9)*([1]A1!$C$9:$C$175=YEAR($F9)),0)))} -> 3.1884369e+08 | L9: {=IF(EDATE($F9,L$2)>DATE(2025,12,31),"",INDEX([1]A1!I$9:I$175,MATCH(1,--(RIGHT([1]A1!$B$9:$B$175,LEN([1]A1!$B$9:$B$175)-4)=$A9)*([1]A1!$C$9:$C$175=YEAR($F9)),0)))} -> 3.1933202e+08 | M9: {=IF(EDATE($F9,M$2)>DATE(2025,12,31),"",INDEX([1]A1!J$9:J$175,MATCH(1,--(RIGHT([1]A1!$B$9:$B$175,LEN([1]A1!$B$9:$B$175)-4)=$A9)*([1]A1!$C$9:$C$175=YEAR($F9)),0)))} -> 3.1930067e+08 | N9: {=IF(EDATE($F9,N$2)>DATE(2025,12,31),"",INDEX([1]A1!K$9:K$175,MATCH(1,--(RIGHT([1]A1!$B$9:$B$175,LEN([1]A1!$B$9:$B$175)-4)=$A9)*([1]A1!$C$9:$C$175=YEAR($F9)),0)))} -> 3.1952487e+08 | ... FA9: {=IF(EDATE($F9,FA$2)>DATE(2025,12,31),"",INDEX([1]A1!EX$9:EX$175,MATCH(1,--(RIGHT([1]A1!$B$9:$B$175,LEN([1]A1!$B$9:$B$175)-4)=$A9)*([1]A1!$C$9:$C$175=YEAR($F9)),0)))}
A10: Professional Lines | B10: Net Written Premium | C10: All | D10: UW Year | E10: USD | F10: =EDATE(F9,12) -> 41275 | G10: {=IF(EDATE($F10,G$2)>DATE(2025,12,31),"",INDEX([1]A1!D$9:D$175,MATCH(1,--(RIGHT([1]A1!$B$9:$B$175,LEN([1]A1!$B$9:$B$175)-4)=$A10)*([1]A1!$C$9:$C$175=YEAR($F10)),0)))} -> 2.0895985e+08 | H10: {=IF(EDATE($F10,H$2)>DATE(2025,12,31),"",INDEX([1]A1!E$9:E$175,MATCH(1,--(RIGHT([1]A1!$B$9:$B$175,LEN([1]A1!$B$9:$B$175)-4)=$A10)*([1]A1!$C$9:$C$175=YEAR($F10)),0)))} -> 4.1478955e+08 | I10: {=IF(EDATE($F10,I$2)>DATE(2025,12,31),"",INDEX([1]A1!F$9:F$175,MATCH(1,--(RIGHT([1]A1!$B$9:$B$175,LEN([1]A1!$B$9:$B$175)-4)=$A10)*([1]A1!$C$9:$C$175=YEAR($F10)),0)))} -> 4.1044628e+08 | J10: {=IF(EDATE($F10,J$2)>DATE(2025,12,31),"",INDEX([1]A1!G$9:G$175,MATCH(1,--(RIGHT([1]A1!$B$9:$B$175,LEN([1]A1!$B$9:$B$175)-4)=$A10)*([1]A1!$C$9:$C$175=YEAR($F10)),0)))} -> 4.1445328e+08 | K10: {=IF(EDATE($F10,K$2)>DATE(2025,12,31),"",INDEX([1]A1!H$9:H$175,MATCH(1,--(RIGHT([1]A1!$B$9:$B$175,LEN([1]A1!$B$9:$B$175)-4)=$A10)*([1]A1!$C$9:$C$175=YEAR($F10)),0)))} -> 4.1756304e+08 | L10: {=IF(EDATE($F10,L$2)>DATE(2025,12,31),"",INDEX([1]A1!I$9:I$175,MATCH(1,--(RIGHT([1]A1!$B$9:$B$175,LEN([1]A1!$B$9:$B$175)-4)=$A10)*([1]A1!$C$9:$C$175=YEAR($F10)),0)))} -> 4.1837472e+08 | M10: {=IF(EDATE($F10,M$2)>DATE(2025,12,31),"",INDEX([1]A1!J$9:J$175,MATCH(1,--(RIGHT([1]A1!$B$9:$B$175,LEN([1]A1!$B$9:$B$175)-4)=$A10)*([1]A1!$C$9:$C$175=YEAR($F10)),0)))} -> 4.1754281e+08 | N10: {=IF(EDATE($F10,N$2)>DATE(2025,12,31),"",INDEX([1]A1!K$9:K$175,MATCH(1,--(RIGHT([1]A1!$B$9:$B$175,LEN([1]A1!$B$9:$B$175)-4)=$A10)*([1]A1!$C$9:$C$175=YEAR($F10)),0)))} -> 4.1783407e+08 | ... FA10: {=IF(EDATE($F10,FA$2)>DATE(2025,12,31),"",INDEX([1]A1!EX$9:EX$175,MATCH(1,--(RIGHT([1]A1!$B$9:$B$175,LEN([1]A1!$B$9:$B$175)-4)=$A10)*([1]A1!$C$9:$C$175=YEAR($F10)),0)))}
A11: Professional Lines | B11: Net Written Premium | C11: All | D11: UW Year | E11: USD | F11: =EDATE(F10,12) -> 41640 | G11: {=IF(EDATE($F11,G$2)>DATE(2025,12,31),"",INDEX([1]A1!D$9:D$175,MATCH(1,--(RIGHT([1]A1!$B$9:$B$175,LEN([1]A1!$B$9:$B$175)-4)=$A11)*([1]A1!$C$9:$C$175=YEAR($F11)),0)))} -> 1.7253629e+08 | H11: {=IF(EDATE($F11,H$2)>DATE(2025,12,31),"",INDEX([1]A1!E$9:E$175,MATCH(1,--(RIGHT([1]A1!$B$9:$B$175,LEN([1]A1!$B$9:$B$175)-4)=$A11)*([1]A1!$C$9:$C$175=YEAR($F11)),0)))} -> 2.4663313e+08 | I11: {=IF(EDATE($F11,I$2)>DATE(2025,12,31),"",INDEX([1]A1!F$9:F$175,MATCH(1,--(RIGHT([1]A1!$B$9:$B$175,LEN([1]A1!$B$9:$B$175)-4)=$A11)*([1]A1!$C$9:$C$175=YEAR($F11)),0)))} -> 2.3966737e+08 | J11: {=IF(EDATE($F11,J$2)>DATE(2025,12,31),"",INDEX([1]A1!G$9:G$175,MATCH(1,--(RIGHT([1]A1!$B$9:$B$175,LEN([1]A1!$B$9:$B$175)-4)=$A11)*([1]A1!$C$9:$C$175=YEAR($F11)),0)))} -> 2.4163005e+08 | K11: {=IF(EDATE($F11,K$2)>DATE(2025,12,31),"",INDEX([1]A1!H$9:H$175,MATCH(1,--(RIGHT([1]A1!$B$9:$B$175,LEN([1]A1!$B$9:$B$175)-4)=$A11)*([1]A1!$C$9:$C$175=YEAR($F11)),0)))} -> 2.4354935e+08 | L11: {=IF(EDATE($F11,L$2)>DATE(2025,12,31),"",INDEX([1]A1!I$9:I$175,MATCH(1,--(RIGHT([1]A1!$B$9:$B$175,LEN([1]A1!$B$9:$B$175)-4)=$A11)*([1]A1!$C$9:$C$175=YEAR($F11)),0)))} -> 2.4279856e+08 | M11: {=IF(EDATE($F11,M$2)>DATE(2025,12,31),"",INDEX([1]A1!J$9:J$175,MATCH(1,--(RIGHT([1]A1!$B$9:$B$175,LEN([1]A1!$B$9:$B$175)-4)=$A11)*([1]A1!$C$9:$C$175=YEAR($F11)),0)))} -> 2.4258029e+08 | N11: {=IF(EDATE($F11,N$2)>DATE(2025,12,31),"",INDEX([1]A1!K$9:K$175,MATCH(1,--(RIGHT([1]A1!$B$9:$B$175,LEN([1]A1!$B$9:$B$175)-4)=$A11)*([1]A1!$C$9:$C$175=YEAR($F11)),0)))} -> 2.4278028e+08 | ... FA11: {=IF(EDATE($F11,FA$2)>DATE(2025,12,31),"",INDEX([1]A1!EX$9:EX$175,MATCH(1,--(RIGHT([1]A1!$B$9:$B$175,LEN([1]A1!$B$9:$B$175)-4)=$A11)*([1]A1!$C$9:$C$175=YEAR($F11)),0)))}
A12: Professional Lines | B12: Net Written Premium | C12: All | D12: UW Year | E12: USD | F12: =EDATE(F11,12) -> 42005 | G12: {=IF(EDATE($F12,G$2)>DATE(2025,12,31),"",INDEX([1]A1!D$9:D$175,MATCH(1,--(RIGHT([1]A1!$B$9:$B$175,LEN([1]A1!$B$9:$B$175)-4)=$A12)*([1]A1!$C$9:$C$175=YEAR($F12)),0)))} -> 1.8711415e+08 | H12: {=IF(EDATE($F12,H$2)>DATE(2025,12,31),"",INDEX([1]A1!E$9:E$175,MATCH(1,--(RIGHT([1]A1!$B$9:$B$175,LEN([1]A1!$B$9:$B$175)-4)=$A12)*([1]A1!$C$9:$C$175=YEAR($F12)),0)))} -> 2.7778126e+08 | I12: {=IF(EDATE($F12,I$2)>DATE(2025,12,31),"",INDEX([1]A1!F$9:F$175,MATCH(1,--(RIGHT([1]A1!$B$9:$B$175,LEN([1]A1!$B$9:$B$175)-4)=$A12)*([1]A1!$C$9:$C$175=YEAR($F12)),0)))} -> 2.7361984e+08 | J12: {=IF(EDATE($F12,J$2)>DATE(2025,12,31),"",INDEX([1]A1!G$9:G$175,MATCH(1,--(RIGHT([1]A1!$B$9:$B$175,LEN([1]A1!$B$9:$B$175)-4)=$A12)*([1]A1!$C$9:$C$175=YEAR($F12)),0)))} -> 2.7223321e+08 | K12: {=IF(EDATE($F12,K$2)>DATE(2025,12,31),"",INDEX([1]A1!H$9:H$175,MATCH(1,--(RIGHT([1]A1!$B$9:$B$175,LEN([1]A1!$B$9:$B$175)-4)=$A12)*([1]A1!$C$9:$C$175=YEAR($F12)),0)))} -> 2.7319895e+08 | L12: {=IF(EDATE($F12,L$2)>DATE(2025,12,31),"",INDEX([1]A1!I$9:I$175,MATCH(1,--(RIGHT([1]A1!$B$9:$B$175,LEN([1]A1!$B$9:$B$175)-4)=$A12)*([1]A1!$C$9:$C$175=YEAR($F12)),0)))} -> 2.7394789e+08 | M12: {=IF(EDATE($F12,M$2)>DATE(2025,12,31),"",INDEX([1]A1!J$9:J$175,MATCH(1,--(RIGHT([1]A1!$B$9:$B$175,LEN([1]A1!$B$9:$B$175)-4)=$A12)*([1]A1!$C$9:$C$175=YEAR($F12)),0)))} -> 2.7466413e+08 | N12: {=IF(EDATE($F12,N$2)>DATE(2025,12,31),"",INDEX([1]A1!K$9:K$175,MATCH(1,--(RIGHT([1]A1!$B$9:$B$175,LEN([1]A1!$B$9:$B$175)-4)=$A12)*([1]A1!$C$9:$C$175=YEAR($F12)),0)))} -> 2.7499626e+08 | ... FA12: {=IF(EDATE($F12,FA$2)>DATE(2025,12,31),"",INDEX([1]A1!EX$9:EX$175,MATCH(1,--(RIGHT([1]A1!$B$9:$B$175,LEN([1]A1!$B$9:$B$175)-4)=$A12)*([1]A1!$C$9:$C$175=YEAR($F12)),0)))}
A13: Professional Lines | B13: Net Written Premium | C13: All | D13: UW Year | E13: USD | F13: =EDATE(F12,12) -> 42370 | G13: {=IF(EDATE($F13,G$2)>DATE(2025,12,31),"",INDEX([1]A1!D$9:D$175,MATCH(1,--(RIGHT([1]A1!$B$9:$B$175,LEN([1]A1!$B$9:$B$175)-4)=$A13)*([1]A1!$C$9:$C$175=YEAR($F13)),0)))} -> 2.2105328e+08 | H13: {=IF(EDATE($F13,H$2)>DATE(2025,12,31),"",INDEX([1]A1!E$9:E$175,MATCH(1,--(RIGHT([1]A1!$B$9:$B$175,LEN([1]A1!$B$9:$B$175)-4)=$A13)*([1]A1!$C$9:$C$175=YEAR($F13)),0)))} -> 2.5465534e+08 | I13: {=IF(EDATE($F13,I$2)>DATE(2025,12,31),"",INDEX([1]A1!F$9:F$175,MATCH(1,--(RIGHT([1]A1!$B$9:$B$175,LEN([1]A1!$B$9:$B$175)-4)=$A13)*([1]A1!$C$9:$C$175=YEAR($F13)),0)))} -> 2.5428519e+08 | J13: {=IF(EDATE($F13,J$2)>DATE(2025,12,31),"",INDEX([1]A1!G$9:G$175,MATCH(1,--(RIGHT([1]A1!$B$9:$B$175,LEN([1]A1!$B$9:$B$175)-4)=$A13)*([1]A1!$C$9:$C$175=YEAR($F13)),0)))} -> 2.5634106e+08 | K13: {=IF(EDATE($F13,K$2)>DATE(2025,12,31),"",INDEX([1]A1!H$9:H$175,MATCH(1,--(RIGHT([1]A1!$B$9:$B$175,LEN([1]A1!$B$9:$B$175)-4)=$A13)*([1]A1!$C$9:$C$175=YEAR($F13)),0)))} -> 2.579356e+08 | L13: {=IF(EDATE($F13,L$2)>DATE(2025,12,31),"",INDEX([1]A1!I$9:I$175,MATCH(1,--(RIGHT([1]A1!$B$9:$B$175,LEN([1]A1!$B$9:$B$175)-4)=$A13)*([1]A1!$C$9:$C$175=YEAR($F13)),0)))} -> 2.5813212e+08 | M13: {=IF(EDATE($F13,M$2)>DATE(2025,12,31),"",INDEX([1]A1!J$9:J$175,MATCH(1,--(RIGHT([1]A1!$B$9:$B$175,LEN([1]A1!$B$9:$B$175)-4)=$A13)*([1]A1!$C$9:$C$175=YEAR($F13)),0)))} -> 2.5820069e+08 | N13: {=IF(EDATE($F13,N$2)>DATE(2025,12,31),"",INDEX([1]A1!K$9:K$175,MATCH(1,--(RIGHT([1]A1!$B$9:$B$175,LEN([1]A1!$B$9:$B$175)-4)=$A13)*([1]A1!$C$9:$C$175=YEAR($F13)),0)))} -> 2.584015e+08 | ... FA13: {=IF(EDATE($F13,FA$2)>DATE(2025,12,31),"",INDEX([1]A1!EX$9:EX$175,MATCH(1,--(RIGHT([1]A1!$B$9:$B$175,LEN([1]A1!$B$9:$B$175)-4)=$A13)*([1]A1!$C$9:$C$175=YEAR($F13)),0)))}
A14: Professional Lines | B14: Net Written Premium | C14: All | D14: UW Year | E14: USD | F14: =EDATE(F13,12) -> 42736 | G14: {=IF(EDATE($F14,G$2)>DATE(2025,12,31),"",INDEX([1]A1!D$9:D$175,MATCH(1,--(RIGHT([1]A1!$B$9:$B$175,LEN([1]A1!$B$9:$B$175)-4)=$A14)*([1]A1!$C$9:$C$175=YEAR($F14)),0)))} -> 2.2514495e+08 | H14: {=IF(EDATE($F14,H$2)>DATE(2025,12,31),"",INDEX([1]A1!E$9:E$175,MATCH(1,--(RIGHT([1]A1!$B$9:$B$175,LEN([1]A1!$B$9:$B$175)-4)=$A14)*([1]A1!$C$9:$C$175=YEAR($F14)),0)))} -> 2.5374203e+08 | I14: {=IF(EDATE($F14,I$2)>DATE(2025,12,31),"",INDEX([1]A1!F$9:F$175,MATCH(1,--(RIGHT([1]A1!$B$9:$B$175,LEN([1]A1!$B$9:$B$175)-4)=$A14)*([1]A1!$C$9:$C$175=YEAR($F14)),0)))} -> 2.6124036e+08 | J14: {=IF(EDATE($F14,J$2)>DATE(2025,12,31),"",INDEX([1]A1!G$9:G$175,MATCH(1,--(RIGHT([1]A1!$B$9:$B$175,LEN([1]A1!$B$9:$B$175)-4)=$A14)*([1]A1!$C$9:$C$175=YEAR($F14)),0)))} -> 2.604496e+08 | K14: {=IF(EDATE($F14,K$2)>DATE(2025,12,31),"",INDEX([1]A1!H$9:H$175,MATCH(1,--(RIGHT([1]A1!$B$9:$B$175,LEN([1]A1!$B$9:$B$175)-4)=$A14)*([1]A1!$C$9:$C$175=YEAR($F14)),0)))} -> 2.6232945e+08 | L14: {=IF(EDATE($F14,L$2)>DATE(2025,12,31),"",INDEX([1]A1!I$9:I$175,MATCH(1,--(RIGHT([1]A1!$B$9:$B$175,LEN([1]A1!$B$9:$B$175)-4)=$A14)*([1]A1!$C$9:$C$175=YEAR($F14)),0)))} -> 2.6279266e+08 | M14: {=IF(EDATE($F14,M$2)>DATE(2025,12,31),"",INDEX([1]A1!J$9:J$175,MATCH(1,--(RIGHT([1]A1!$B$9:$B$175,LEN([1]A1!$B$9:$B$175)-4)=$A14)*([1]A1!$C$9:$C$175=YEAR($F14)),0)))} -> 2.6265518e+08 | N14: {=IF(EDATE($F14,N$2)>DATE(2025,12,31),"",INDEX([1]A1!K$9:K$175,MATCH(1,--(RIGHT([1]A1!$B$9:$B$175,LEN([1]A1!$B$9:$B$175)-4)=$A14)*([1]A1!$C$9:$C$175=YEAR($F14)),0)))} -> 2.6289769e+08 | ... FA14: {=IF(EDATE($F14,FA$2)>DATE(2025,12,31),"",INDEX([1]A1!EX$9:EX$175,MATCH(1,--(RIGHT([1]A1!$B$9:$B$175,LEN([1]A1!$B$9:$B$175)-4)=$A14)*([1]A1!$C$9:$C$175=YEAR($F14)),0)))}
A15: Professional Lines | B15: Net Written Premium | C15: All | D15: UW Year | E15: USD | F15: =EDATE(F14,12) -> 43101 | G15: {=IF(EDATE($F15,G$2)>DATE(2025,12,31),"",INDEX([1]A1!D$9:D$175,MATCH(1,--(RIGHT([1]A1!$B$9:$B$175,LEN([1]A1!$B$9:$B$175)-4)=$A15)*([1]A1!$C$9:$C$175=YEAR($F15)),0)))} -> 2.5081672e+08 | H15: {=IF(EDATE($F15,H$2)>DATE(2025,12,31),"",INDEX([1]A1!E$9:E$175,MATCH(1,--(RIGHT([1]A1!$B$9:$B$175,LEN([1]A1!$B$9:$B$175)-4)=$A15)*([1]A1!$C$9:$C$175=YEAR($F15)),0)))} -> 2.726728e+08 | I15: {=IF(EDATE($F15,I$2)>DATE(2025,12,31),"",INDEX([1]A1!F$9:F$175,MATCH(1,--(RIGHT([1]A1!$B$9:$B$175,LEN([1]A1!$B$9:$B$175)-4)=$A15)*([1]A1!$C$9:$C$175=YEAR($F15)),0)))} -> 2.8349804e+08 | J15: {=IF(EDATE($F15,J$2)>DATE(2025,12,31),"",INDEX([1]A1!G$9:G$175,MATCH(1,--(RIGHT([1]A1!$B$9:$B$175,LEN([1]A1!$B$9:$B$175)-4)=$A15)*([1]A1!$C$9:$C$175=YEAR($F15)),0)))} -> 2.8762692e+08 | K15: {=IF(EDATE($F15,K$2)>DATE(2025,12,31),"",INDEX([1]A1!H$9:H$175,MATCH(1,--(RIGHT([1]A1!$B$9:$B$175,LEN([1]A1!$B$9:$B$175)-4)=$A15)*([1]A1!$C$9:$C$175=YEAR($F15)),0)))} -> 2.8856511e+08 | L15: {=IF(EDATE($F15,L$2)>DATE(2025,12,31),"",INDEX([1]A1!I$9:I$175,MATCH(1,--(RIGHT([1]A1!$B$9:$B$175,LEN([1]A1!$B$9:$B$175)-4)=$A15)*([1]A1!$C$9:$C$175=YEAR($F15)),0)))} -> 2.8989975e+08 | M15: {=IF(EDATE($F15,M$2)>DATE(2025,12,31),"",INDEX([1]A1!J$9:J$175,MATCH(1,--(RIGHT([1]A1!$B$9:$B$175,LEN([1]A1!$B$9:$B$175)-4)=$A15)*([1]A1!$C$9:$C$175=YEAR($F15)),0)))} -> 2.9011652e+08 | N15: {=IF(EDATE($F15,N$2)>DATE(2025,12,31),"",INDEX([1]A1!K$9:K$175,MATCH(1,--(RIGHT([1]A1!$B$9:$B$175,LEN([1]A1!$B$9:$B$175)-4)=$A15)*([1]A1!$C$9:$C$175=YEAR($F15)),0)))} -> 2.9016376e+08 | ... FA15: {=IF(EDATE($F15,FA$2)>DATE(2025,12,31),"",INDEX([1]A1!EX$9:EX$175,MATCH(1,--(RIGHT([1]A1!$B$9:$B$175,LEN([1]A1!$B$9:$B$175)-4)=$A15)*([1]A1!$C$9:$C$175=YEAR($F15)),0)))}
... A22: Professional Lines | B22: Net Written Premium | C22: All | D22: UW Year | E22: USD | F22: =EDATE(F21,12) -> 45658 | G22: {=IF(EDATE($F22,G$2)>DATE(2025,12,31),"",INDEX([1]A1!D$9:D$175,MATCH(1,--(RIGHT([1]A1!$B$9:$B$175,LEN([1]A1!$B$9:$B$175)-4)=$A22)*([1]A1!$C$9:$C$175=YEAR($F22)),0)))} -> 2.0142324e+08 | H22: {=IF(EDATE($F22,H$2)>DATE(2025,12,31),"",INDEX([1]A1!E$9:E$175,MATCH(1,--(RIGHT([1]A1!$B$9:$B$175,LEN([1]A1!$B$9:$B$175)-4)=$A22)*([1]A1!$C$9:$C$175=YEAR($F22)),0)))} | I22: {=IF(EDATE($F22,I$2)>DATE(2025,12,31),"",INDEX([1]A1!F$9:F$175,MATCH(1,--(RIGHT([1]A1!$B$9:$B$175,LEN([1]A1!$B$9:$B$175)-4)=$A22)*([1]A1!$C$9:$C$175=YEAR($F22)),0)))} | J22: {=IF(EDATE($F22,J$2)>DATE(2025,12,31),"",INDEX([1]A1!G$9:G$175,MATCH(1,--(RIGHT([1]A1!$B$9:$B$175,LEN([1]A1!$B$9:$B$175)-4)=$A22)*([1]A1!$C$9:$C$175=YEAR($F22)),0)))} | K22: {=IF(EDATE($F22,K$2)>DATE(2025,12,31),"",INDEX([1]A1!H$9:H$175,MATCH(1,--(RIGHT([1]A1!$B$9:$B$175,LEN([1]A1!$B$9:$B$175)-4)=$A22)*([1]A1!$C$9:$C$175=YEAR($F22)),0)))} | L22: {=IF(EDATE($F22,L$2)>DATE(2025,12,31),"",INDEX([1]A1!I$9:I$175,MATCH(1,--(RIGHT([1]A1!$B$9:$B$175,LEN([1]A1!$B$9:$B$175)-4)=$A22)*([1]A1!$C$9:$C$175=YEAR($F22)),0)))} | M22: {=IF(EDATE($F22,M$2)>DATE(2025,12,31),"",INDEX([1]A1!J$9:J$175,MATCH(1,--(RIGHT([1]A1!$B$9:$B$175,LEN([1]A1!$B$9:$B$175)-4)=$A22)*([1]A1!$C$9:$C$175=YEAR($F22)),0)))} | N22: {=IF(EDATE($F22,N$2)>DATE(2025,12,31),"",INDEX([1]A1!K$9:K$175,MATCH(1,--(RIGHT([1]A1!$B$9:$B$175,LEN([1]A1!$B$9:$B$175)-4)=$A22)*([1]A1!$C$9:$C$175=YEAR($F22)),0)))} | ... FA22: {=IF(EDATE($F22,FA$2)>DATE(2025,12,31),"",INDEX([1]A1!EX$9:EX$175,MATCH(1,--(RIGHT([1]A1!$B$9:$B$175,LEN([1]A1!$B$9:$B$175)-4)=$A22)*([1]A1!$C$9:$C$175=YEAR($F22)),0)))}
A24: Liability | B24: Net Written Premium | C24: All | D24: UW Year | E24: USD | F24: =triangle_start_date -> 38718 | G24: {=IF(EDATE($F24,G$2)>DATE(2025,12,31),"",INDEX([1]A1!D$9:D$175,MATCH(1,--(RIGHT([1]A1!$B$9:$B$175,LEN([1]A1!$B$9:$B$175)-4)=$A24)*([1]A1!$C$9:$C$175=YEAR($F24)),0)))} -> 69065431 | H24: {=IF(EDATE($F24,H$2)>DATE(2025,12,31),"",INDEX([1]A1!E$9:E$175,MATCH(1,--(RIGHT([1]A1!$B$9:$B$175,LEN([1]A1!$B$9:$B$175)-4)=$A24)*([1]A1!$C$9:$C$175=YEAR($F24)),0)))} -> 1.3355061e+08 | I24: {=IF(EDATE($F24,I$2)>DATE(2025,12,31),"",INDEX([1]A1!F$9:F$175,MATCH(1,--(RIGHT([1]A1!$B$9:$B$175,LEN([1]A1!$B$9:$B$175)-4)=$A24)*([1]A1!$C$9:$C$175=YEAR($F24)),0)))} -> 1.4327316e+08 | J24: {=IF(EDATE($F24,J$2)>DATE(2025,12,31),"",INDEX([1]A1!G$9:G$175,MATCH(1,--(RIGHT([1]A1!$B$9:$B$175,LEN([1]A1!$B$9:$B$175)-4)=$A24)*([1]A1!$C$9:$C$175=YEAR($F24)),0)))} -> 1.4434176e+08 | K24: {=IF(EDATE($F24,K$2)>DATE(2025,12,31),"",INDEX([1]A1!H$9:H$175,MATCH(1,--(RIGHT([1]A1!$B$9:$B$175,LEN([1]A1!$B$9:$B$175)-4)=$A24)*([1]A1!$C$9:$C$175=YEAR($F24)),0)))} -> 1.428303e+08 | L24: {=IF(EDATE($F24,L$2)>DATE(2025,12,31),"",INDEX([1]A1!I$9:I$175,MATCH(1,--(RIGHT([1]A1!$B$9:$B$175,LEN([1]A1!$B$9:$B$175)-4)=$A24)*([1]A1!$C$9:$C$175=YEAR($F24)),0)))} -> 1.428155e+08 | M24: {=IF(EDATE($F24,M$2)>DATE(2025,12,31),"",INDEX([1]A1!J$9:J$175,MATCH(1,--(RIGHT([1]A1!$B$9:$B$175,LEN([1]A1!$B$9:$B$175)-4)=$A24)*([1]A1!$C$9:$C$175=YEAR($F24)),0)))} -> 1.4287384e+08 | N24: {=IF(EDATE($F24,N$2)>DATE(2025,12,31),"",INDEX([1]A1!K$9:K$175,MATCH(1,--(RIGHT([1]A1!$B$9:$B$175,LEN([1]A1!$B$9:$B$175)-4)=$A24)*([1]A1!$C$9:$C$175=YEAR($F24)),0)))} -> 1.4323372e+08 | ... FA24: {=IF(EDATE($F24,FA$2)>DATE(2025,12,31),"",INDEX([1]A1!EX$9:EX$175,MATCH(1,--(RIGHT([1]A1!$B$9:$B$175,LEN([1]A1!$B$9:$B$175)-4)=$A24)*([1]A1!$C$9:$C$175=YEAR($F24)),0)))}
A25: Liability | B25: Net Written Premium | C25: All | D25: UW Year | E25: USD | F25: =EDATE(F24,12) -> 39083 | G25: {=IF(EDATE($F25,G$2)>DATE(2025,12,31),"",INDEX([1]A1!D$9:D$175,MATCH(1,--(RIGHT([1]A1!$B$9:$B$175,LEN([1]A1!$B$9:$B$175)-4)=$A25)*([1]A1!$C$9:$C$175=YEAR($F25)),0)))} -> 72721921 | H25: {=IF(EDATE($F25,H$2)>DATE(2025,12,31),"",INDEX([1]A1!E$9:E$175,MATCH(1,--(RIGHT([1]A1!$B$9:$B$175,LEN([1]A1!$B$9:$B$175)-4)=$A25)*([1]A1!$C$9:$C$175=YEAR($F25)),0)))} -> 1.4357973e+08 | I25: {=IF(EDATE($F25,I$2)>DATE(2025,12,31),"",INDEX([1]A1!F$9:F$175,MATCH(1,--(RIGHT([1]A1!$B$9:$B$175,LEN([1]A1!$B$9:$B$175)-4)=$A25)*([1]A1!$C$9:$C$175=YEAR($F25)),0)))} -> 1.5503057e+08 | J25: {=IF(EDATE($F25,J$2)>DATE(2025,12,31),"",INDEX([1]A1!G$9:G$175,MATCH(1,--(RIGHT([1]A1!$B$9:$B$175,LEN([1]A1!$B$9:$B$175)-4)=$A25)*([1]A1!$C$9:$C$175=YEAR($F25)),0)))} -> 1.5666513e+08 | K25: {=IF(EDATE($F25,K$2)>DATE(2025,12,31),"",INDEX([1]A1!H$9:H$175,MATCH(1,--(RIGHT([1]A1!$B$9:$B$175,LEN([1]A1!$B$9:$B$175)-4)=$A25)*([1]A1!$C$9:$C$175=YEAR($F25)),0)))} -> 1.5694078e+08 | L25: {=IF(EDATE($F25,L$2)>DATE(2025,12,31),"",INDEX([1]A1!I$9:I$175,MATCH(1,--(RIGHT([1]A1!$B$9:$B$175,LEN([1]A1!$B$9:$B$175)-4)=$A25)*([1]A1!$C$9:$C$175=YEAR($F25)),0)))} -> 1.5692173e+08 | M25: {=IF(EDATE($F25,M$2)>DATE(2025,12,31),"",INDEX([1]A1!J$9:J$175,MATCH(1,--(RIGHT([1]A1!$B$9:$B$175,LEN([1]A1!$B$9:$B$175)-4)=$A25)*([1]A1!$C$9:$C$175=YEAR($F25)),0)))} -> 1.5697278e+08 | N25: {=IF(EDATE($F25,N$2)>DATE(2025,12,31),"",INDEX([1]A1!K$9:K$175,MATCH(1,--(RIGHT([1]A1!$B$9:$B$175,LEN([1]A1!$B$9:$B$175)-4)=$A25)*([1]A1!$C$9:$C$175=YEAR($F25)),0)))} -> 1.5707628e+08 | ... FA25: {=IF(EDATE($F25,FA$2)>DATE(2025,12,31),"",INDEX([1]A1!EX$9:EX$175,MATCH(1,--(RIGHT([1]A1!$B$9:$B$175,LEN([1]A1!$B$9:$B$175)-4)=$A25)*([1]A1!$C$9:$C$175=YEAR($F25)),0)))}
A26: Liability | B26: Net Written Premium | C26: All | D26: UW Year | E26: USD | F26: =EDATE(F25,12) -> 39448 | G26: {=IF(EDATE($F26,G$2)>DATE(2025,12,31),"",INDEX([1]A1!D$9:D$175,MATCH(1,--(RIGHT([1]A1!$B$9:$B$175,LEN([1]A1!$B$9:$B$175)-4)=$A26)*([1]A1!$C$9:$C$175=YEAR($F26)),0)))} -> 72553331 | H26: {=IF(EDATE($F26,H$2)>DATE(2025,12,31),"",INDEX([1]A1!E$9:E$175,MATCH(1,--(RIGHT([1]A1!$B$9:$B$175,LEN([1]A1!$B$9:$B$175)-4)=$A26)*([1]A1!$C$9:$C$175=YEAR($F26)),0)))} -> 1.390936e+08 | I26: {=IF(EDATE($F26,I$2)>DATE(2025,12,31),"",INDEX([1]A1!F$9:F$175,MATCH(1,--(RIGHT([1]A1!$B$9:$B$175,LEN([1]A1!$B$9:$B$175)-4)=$A26)*([1]A1!$C$9:$C$175=YEAR($F26)),0)))} -> 1.4164443e+08 | J26: {=IF(EDATE($F26,J$2)>DATE(2025,12,31),"",INDEX([1]A1!G$9:G$175,MATCH(1,--(RIGHT([1]A1!$B$9:$B$175,LEN([1]A1!$B$9:$B$175)-4)=$A26)*([1]A1!$C$9:$C$175=YEAR($F26)),0)))} -> 1.4224735e+08 | K26: {=IF(EDATE($F26,K$2)>DATE(2025,12,31),"",INDEX([1]A1!H$9:H$175,MATCH(1,--(RIGHT([1]A1!$B$9:$B$175,LEN([1]A1!$B$9:$B$175)-4)=$A26)*([1]A1!$C$9:$C$175=YEAR($F26)),0)))} -> 1.442114e+08 | L26: {=IF(EDATE($F26,L$2)>DATE(2025,12,31),"",INDEX([1]A1!I$9:I$175,MATCH(1,--(RIGHT([1]A1!$B$9:$B$175,LEN([1]A1!$B$9:$B$175)-4)=$A26)*([1]A1!$C$9:$C$175=YEAR($F26)),0)))} -> 1.4500263e+08 | M26: {=IF(EDATE($F26,M$2)>DATE(2025,12,31),"",INDEX([1]A1!J$9:J$175,MATCH(1,--(RIGHT([1]A1!$B$9:$B$175,LEN([1]A1!$B$9:$B$175)-4)=$A26)*([1]A1!$C$9:$C$175=YEAR($F26)),0)))} -> 1.451363e+08 | N26: {=IF(EDATE($F26,N$2)>DATE(2025,12,31),"",INDEX([1]A1!K$9:K$175,MATCH(1,--(RIGHT([1]A1!$B$9:$B$175,LEN([1]A1!$B$9:$B$175)-4)=$A26)*([1]A1!$C$9:$C$175=YEAR($F26)),0)))} -> 1.4517889e+08 | ... FA26: {=IF(EDATE($F26,FA$2)>DATE(2025,12,31),"",INDEX([1]A1!EX$9:EX$175,MATCH(1,--(RIGHT([1]A1!$B$9:$B$175,LEN([1]A1!$B$9:$B$175)-4)=$A26)*([1]A1!$C$9:$C$175=YEAR($F26)),0)))}
A27: Liability | B27: Net Written Premium | C27: All | D27: UW Year | E27: USD | F27: =EDATE(F26,12) -> 39814 | G27: {=IF(EDATE($F27,G$2)>DATE(2025,12,31),"",INDEX([1]A1!D$9:D$175,MATCH(1,--(RIGHT([1]A1!$B$9:$B$175,LEN([1]A1!$B$9:$B$175)-4)=$A27)*([1]A1!$C$9:$C$175=YEAR($F27)),0)))} -> 1.0212799e+08 | H27: {=IF(EDATE($F27,H$2)>DATE(2025,12,31),"",INDEX([1]A1!E$9:E$175,MATCH(1,--(RIGHT([1]A1!$B$9:$B$175,LEN([1]A1!$B$9:$B$175)-4)=$A27)*([1]A1!$C$9:$C$175=YEAR($F27)),0)))} -> 1.943446e+08 | I27: {=IF(EDATE($F27,I$2)>DATE(2025,12,31),"",INDEX([1]A1!F$9:F$175,MATCH(1,--(RIGHT([1]A1!$B$9:$B$175,LEN([1]A1!$B$9:$B$175)-4)=$A27)*([1]A1!$C$9:$C$175=YEAR($F27)),0)))} -> 2.1501244e+08 | J27: {=IF(EDATE($F27,J$2)>DATE(2025,12,31),"",INDEX([1]A1!G$9:G$175,MATCH(1,--(RIGHT([1]A1!$B$9:$B$175,LEN([1]A1!$B$9:$B$175)-4)=$A27)*([1]A1!$C$9:$C$175=YEAR($F27)),0)))} -> 2.1718603e+08 | K27: {=IF(EDATE($F27,K$2)>DATE(2025,12,31),"",INDEX([1]A1!H$9:H$175,MATCH(1,--(RIGHT([1]A1!$B$9:$B$175,LEN([1]A1!$B$9:$B$175)-4)=$A27)*([1]A1!$C$9:$C$175=YEAR($F27)),0)))} -> 2.1714994e+08 | L27: {=IF(EDATE($F27,L$2)>DATE(2025,12,31),"",INDEX([1]A1!I$9:I$175,MATCH(1,--(RIGHT([1]A1!$B$9:$B$175,LEN([1]A1!$B$9:$B$175)-4)=$A27)*([1]A1!$C$9:$C$175=YEAR($F27)),0)))} -> 2.1885141e+08 | M27: {=IF(EDATE($F27,M$2)>DATE(2025,12,31),"",INDEX([1]A1!J$9:J$175,MATCH(1,--(RIGHT([1]A1!$B$9:$B$175,LEN([1]A1!$B$9:$B$175)-4)=$A27)*([1]A1!$C$9:$C$175=YEAR($F27)),0)))} -> 2.1886555e+08 | N27: {=IF(EDATE($F27,N$2)>DATE(2025,12,31),"",INDEX([1]A1!K$9:K$175,MATCH(1,--(RIGHT([1]A1!$B$9:$B$175,LEN([1]A1!$B$9:$B$175)-4)=$A27)*([1]A1!$C$9:$C$175=YEAR($F27)),0)))} -> 2.1886872e+08 | ... FA27: {=IF(EDATE($F27,FA$2)>DATE(2025,12,31),"",INDEX([1]A1!EX$9:EX$175,MATCH(1,--(RIGHT([1]A1!$B$9:$B$175,LEN([1]A1!$B$9:$B$175)-4)=$A27)*([1]A1!$C$9:$C$175=YEAR($F27)),0)))}
A28: Liability | B28: Net Written Premium | C28: All | D28: UW Year | E28: USD | F28: =EDATE(F27,12) -> 40179 | G28: {=IF(EDATE($F28,G$2)>DATE(2025,12,31),"",INDEX([1]A1!D$9:D$175,MATCH(1,--(RIGHT([1]A1!$B$9:$B$175,LEN([1]A1!$B$9:$B$175)-4)=$A28)*([1]A1!$C$9:$C$175=YEAR($F28)),0)))} -> 88467263 | H28: {=IF(EDATE($F28,H$2)>DATE(2025,12,31),"",INDEX([1]A1!E$9:E$175,MATCH(1,--(RIGHT([1]A1!$B$9:$B$175,LEN([1]A1!$B$9:$B$175)-4)=$A28)*([1]A1!$C$9:$C$175=YEAR($F28)),0)))} -> 1.7453668e+08 | I28: {=IF(EDATE($F28,I$2)>DATE(2025,12,31),"",INDEX([1]A1!F$9:F$175,MATCH(1,--(RIGHT([1]A1!$B$9:$B$175,LEN([1]A1!$B$9:$B$175)-4)=$A28)*([1]A1!$C$9:$C$175=YEAR($F28)),0)))} -> 1.8895982e+08 | J28: {=IF(EDATE($F28,J$2)>DATE(2025,12,31),"",INDEX([1]A1!G$9:G$175,MATCH(1,--(RIGHT([1]A1!$B$9:$B$175,LEN([1]A1!$B$9:$B$175)-4)=$A28)*([1]A1!$C$9:$C$175=YEAR($F28)),0)))} -> 1.8914726e+08 | K28: {=IF(EDATE($F28,K$2)>DATE(2025,12,31),"",INDEX([1]A1!H$9:H$175,MATCH(1,--(RIGHT([1]A1!$B$9:$B$175,LEN([1]A1!$B$9:$B$175)-4)=$A28)*([1]A1!$C$9:$C$175=YEAR($F28)),0)))} -> 1.9086425e+08 | L28: {=IF(EDATE($F28,L$2)>DATE(2025,12,31),"",INDEX([1]A1!I$9:I$175,MATCH(1,--(RIGHT([1]A1!$B$9:$B$175,LEN([1]A1!$B$9:$B$175)-4)=$A28)*([1]A1!$C$9:$C$175=YEAR($F28)),0)))} -> 1.9138707e+08 | M28: {=IF(EDATE($F28,M$2)>DATE(2025,12,31),"",INDEX([1]A1!J$9:J$175,MATCH(1,--(RIGHT([1]A1!$B$9:$B$175,LEN([1]A1!$B$9:$B$175)-4)=$A28)*([1]A1!$C$9:$C$175=YEAR($F28)),0)))} -> 1.9148241e+08 | N28: {=IF(EDATE($F28,N$2)>DATE(2025,12,31),"",INDEX([1]A1!K$9:K$175,MATCH(1,--(RIGHT([1]A1!$B$9:$B$175,LEN([1]A1!$B$9:$B$175)-4)=$A28)*([1]A1!$C$9:$C$175=YEAR($F28)),0)))} -> 1.9168688e+08 | ... FA28: {=IF(EDATE($F28,FA$2)>DATE(2025,12,31),"",INDEX([1]A1!EX$9:EX$175,MATCH(1,--(RIGHT([1]A1!$B$9:$B$175,LEN([1]A1!$B$9:$B$175)-4)=$A28)*([1]A1!$C$9:$C$175=YEAR($F28)),0)))}
A29: Liability | B29: Net Written Premium | C29: All | D29: UW Year | E29: USD | F29: =EDATE(F28,12) -> 40544 | G29: {=IF(EDATE($F29,G$2)>DATE(2025,12,31),"",INDEX([1]A1!D$9:D$175,MATCH(1,--(RIGHT([1]A1!$B$9:$B$175,LEN([1]A1!$B$9:$B$175)-4)=$A29)*([1]A1!$C$9:$C$175=YEAR($F29)),0)))} -> 78597903 | H29: {=IF(EDATE($F29,H$2)>DATE(2025,12,31),"",INDEX([1]A1!E$9:E$175,MATCH(1,--(RIGHT([1]A1!$B$9:$B$175,LEN([1]A1!$B$9:$B$175)-4)=$A29)*([1]A1!$C$9:$C$175=YEAR($F29)),0)))} -> 1.6812891e+08 | I29: {=IF(EDATE($F29,I$2)>DATE(2025,12,31),"",INDEX([1]A1!F$9:F$175,MATCH(1,--(RIGHT([1]A1!$B$9:$B$175,LEN([1]A1!$B$9:$B$175)-4)=$A29)*([1]A1!$C$9:$C$175=YEAR($F29)),0)))} -> 1.8914312e+08 | J29: {=IF(EDATE($F29,J$2)>DATE(2025,12,31),"",INDEX([1]A1!G$9:G$175,MATCH(1,--(RIGHT([1]A1!$B$9:$B$175,LEN([1]A1!$B$9:$B$175)-4)=$A29)*([1]A1!$C$9:$C$175=YEAR($F29)),0)))} -> 1.9319467e+08 | K29: {=IF(EDATE($F29,K$2)>DATE(2025,12,31),"",INDEX([1]A1!H$9:H$175,MATCH(1,--(RIGHT([1]A1!$B$9:$B$175,LEN([1]A1!$B$9:$B$175)-4)=$A29)*([1]A1!$C$9:$C$175=YEAR($F29)),0)))} -> 1.937221e+08 | L29: {=IF(EDATE($F29,L$2)>DATE(2025,12,31),"",INDEX([1]A1!I$9:I$175,MATCH(1,--(RIGHT([1]A1!$B$9:$B$175,LEN([1]A1!$B$9:$B$175)-4)=$A29)*([1]A1!$C$9:$C$175=YEAR($F29)),0)))} -> 1.9435378e+08 | M29: {=IF(EDATE($F29,M$2)>DATE(2025,12,31),"",INDEX([1]A1!J$9:J$175,MATCH(1,--(RIGHT([1]A1!$B$9:$B$175,LEN([1]A1!$B$9:$B$175)-4)=$A29)*([1]A1!$C$9:$C$175=YEAR($F29)),0)))} -> 1.9461564e+08 | N29: {=IF(EDATE($F29,N$2)>DATE(2025,12,31),"",INDEX([1]A1!K$9:K$175,MATCH(1,--(RIGHT([1]A1!$B$9:$B$175,LEN([1]A1!$B$9:$B$175)-4)=$A29)*([1]A1!$C$9:$C$175=YEAR($F29)),0)))} -> 1.9468164e+08 | ... FA29: {=IF(EDATE($F29,FA$2)>DATE(2025,12,31),"",INDEX([1]A1!EX$9:EX$175,MATCH(1,--(RIGHT([1]A1!$B$9:$B$175,LEN([1]A1!$B$9:$B$175)-4)=$A29)*([1]A1!$C$9:$C$175=YEAR($F29)),0)))}
A30: Liability | B30: Net Written Premium | C30: All | D30: UW Year | E30: USD | F30: =EDATE(F29,12) -> 40909 | G30: {=IF(EDATE($F30,G$2)>DATE(2025,12,31),"",INDEX([1]A1!D$9:D$175,MATCH(1,--(RIGHT([1]A1!$B$9:$B$175,LEN([1]A1!$B$9:$B$175)-4)=$A30)*([1]A1!$C$9:$C$175=YEAR($F30)),0)))} -> 85387137 | H30: {=IF(EDATE($F30,H$2)>DATE(2025,12,31),"",INDEX([1]A1!E$9:E$175,MATCH(1,--(RIGHT([1]A1!$B$9:$B$175,LEN([1]A1!$B$9:$B$175)-4)=$A30)*([1]A1!$C$9:$C$175=YEAR($F30)),0)))} -> 1.8383553e+08 | I30: {=IF(EDATE($F30,I$2)>DATE(2025,12,31),"",INDEX([1]A1!F$9:F$175,MATCH(1,--(RIGHT([1]A1!$B$9:$B$175,LEN([1]A1!$B$9:$B$175)-4)=$A30)*([1]A1!$C$9:$C$175=YEAR($F30)),0)))} -> 1.9025438e+08 | J30: {=IF(EDATE($F30,J$2)>DATE(2025,12,31),"",INDEX([1]A1!G$9:G$175,MATCH(1,--(RIGHT([1]A1!$B$9:$B$175,LEN([1]A1!$B$9:$B$175)-4)=$A30)*([1]A1!$C$9:$C$175=YEAR($F30)),0)))} -> 1.9560998e+08 | K30: {=IF(EDATE($F30,K$2)>DATE(2025,12,31),"",INDEX([1]A1!H$9:H$175,MATCH(1,--(RIGHT([1]A1!$B$9:$B$175,LEN([1]A1!$B$9:$B$175)-4)=$A30)*([1]A1!$C$9:$C$175=YEAR($F30)),0)))} -> 1.9588295e+08 | L30: {=IF(EDATE($F30,L$2)>DATE(2025,12,31),"",INDEX([1]A1!I$9:I$175,MATCH(1,--(RIGHT([1]A1!$B$9:$B$175,LEN([1]A1!$B$9:$B$175)-4)=$A30)*([1]A1!$C$9:$C$175=YEAR($F30)),0)))} -> 1.9585657e+08 | M30: {=IF(EDATE($F30,M$2)>DATE(2025,12,31),"",INDEX([1]A1!J$9:J$175,MATCH(1,--(RIGHT([1]A1!$B$9:$B$175,LEN([1]A1!$B$9:$B$175)-4)=$A30)*([1]A1!$C$9:$C$175=YEAR($F30)),0)))} -> 1.9614702e+08 | N30: {=IF(EDATE($F30,N$2)>DATE(2025,12,31),"",INDEX([1]A1!K$9:K$175,MATCH(1,--(RIGHT([1]A1!$B$9:$B$175,LEN([1]A1!$B$9:$B$175)-4)=$A30)*([1]A1!$C$9:$C$175=YEAR($F30)),0)))} -> 1.9626503e+08 | ... FA30: {=IF(EDATE($F30,FA$2)>DATE(2025,12,31),"",INDEX([1]A1!EX$9:EX$175,MATCH(1,--(RIGHT([1]A1!$B$9:$B$175,LEN([1]A1!$B$9:$B$175)-4)=$A30)*([1]A1!$C$9:$C$175=YEAR($F30)),0)))}
A31: Liability | B31: Net Written Premium | C31: All | D31: UW Year | E31: USD | F31: =EDATE(F30,12) -> 41275 | G31: {=IF(EDATE($F31,G$2)>DATE(2025,12,31),"",INDEX([1]A1!D$9:D$175,MATCH(1,--(RIGHT([1]A1!$B$9:$B$175,LEN([1]A1!$B$9:$B$175)-4)=$A31)*([1]A1!$C$9:$C$175=YEAR($F31)),0)))} -> 2.0898819e+08 | H31: {=IF(EDATE($F31,H$2)>DATE(2025,12,31),"",INDEX([1]A1!E$9:E$175,MATCH(1,--(RIGHT([1]A1!$B$9:$B$175,LEN([1]A1!$B$9:$B$175)-4)=$A31)*([1]A1!$C$9:$C$175=YEAR($F31)),0)))} -> 2.278122e+08 | I31: {=IF(EDATE($F31,I$2)>DATE(2025,12,31),"",INDEX([1]A1!F$9:F$175,MATCH(1,--(RIGHT([1]A1!$B$9:$B$175,LEN([1]A1!$B$9:$B$175)-4)=$A31)*([1]A1!$C$9:$C$175=YEAR($F31)),0)))} -> 2.3049679e+08 | J31: {=IF(EDATE($F31,J$2)>DATE(2025,12,31),"",INDEX([1]A1!G$9:G$175,MATCH(1,--(RIGHT([1]A1!$B$9:$B$175,LEN([1]A1!$B$9:$B$175)-4)=$A31)*([1]A1!$C$9:$C$175=YEAR($F31)),0)))} -> 2.332634e+08 | K31: {=IF(EDATE($F31,K$2)>DATE(2025,12,31),"",INDEX([1]A1!H$9:H$175,MATCH(1,--(RIGHT([1]A1!$B$9:$B$175,LEN([1]A1!$B$9:$B$175)-4)=$A31)*([1]A1!$C$9:$C$175=YEAR($F31)),0)))} -> 2.3421773e+08 | L31: {=IF(EDATE($F31,L$2)>DATE(2025,12,31),"",INDEX([1]A1!I$9:I$175,MATCH(1,--(RIGHT([1]A1!$B$9:$B$175,LEN([1]A1!$B$9:$B$175)-4)=$A31)*([1]A1!$C$9:$C$175=YEAR($F31)),0)))} -> 2.3487776e+08 | M31: {=IF(EDATE($F31,M$2)>DATE(2025,12,31),"",INDEX([1]A1!J$9:J$175,MATCH(1,--(RIGHT([1]A1!$B$9:$B$175,LEN([1]A1!$B$9:$B$175)-4)=$A31)*([1]A1!$C$9:$C$175=YEAR($F31)),0)))} -> 2.3535885e+08 | N31: {=IF(EDATE($F31,N$2)>DATE(2025,12,31),"",INDEX([1]A1!K$9:K$175,MATCH(1,--(RIGHT([1]A1!$B$9:$B$175,LEN([1]A1!$B$9:$B$175)-4)=$A31)*([1]A1!$C$9:$C$175=YEAR($F31)),0)))} -> 2.3628031e+08 | ... FA31: {=IF(EDATE($F31,FA$2)>DATE(2025,12,31),"",INDEX([1]A1!EX$9:EX$175,MATCH(1,--(RIGHT([1]A1!$B$9:$B$175,LEN([1]A1!$B$9:$B$175)-4)=$A31)*([1]A1!$C$9:$C$175=YEAR($F31)),0)))}
A32: Liability | B32: Net Written Premium | C32: All | D32: UW Year | E32: USD | F32: =EDATE(F31,12) -> 41640 | G32: {=IF(EDATE($F32,G$2)>DATE(2025,12,31),"",INDEX([1]A1!D$9:D$175,MATCH(1,--(RIGHT([1]A1!$B$9:$B$175,LEN([1]A1!$B$9:$B$175)-4)=$A32)*([1]A1!$C$9:$C$175=YEAR($F32)),0)))} -> 2.2033772e+08 | H32: {=IF(EDATE($F32,H$2)>DATE(2025,12,31),"",INDEX([1]A1!E$9:E$175,MATCH(1,--(RIGHT([1]A1!$B$9:$B$175,LEN([1]A1!$B$9:$B$175)-4)=$A32)*([1]A1!$C$9:$C$175=YEAR($F32)),0)))} -> 2.5069404e+08 | I32: {=IF(EDATE($F32,I$2)>DATE(2025,12,31),"",INDEX([1]A1!F$9:F$175,MATCH(1,--(RIGHT([1]A1!$B$9:$B$175,LEN([1]A1!$B$9:$B$175)-4)=$A32)*([1]A1!$C$9:$C$175=YEAR($F32)),0)))} -> 2.5170677e+08 | J32: {=IF(EDATE($F32,J$2)>DATE(2025,12,31),"",INDEX([1]A1!G$9:G$175,MATCH(1,--(RIGHT([1]A1!$B$9:$B$175,LEN([1]A1!$B$9:$B$175)-4)=$A32)*([1]A1!$C$9:$C$175=YEAR($F32)),0)))} -> 2.5459064e+08 | K32: {=IF(EDATE($F32,K$2)>DATE(2025,12,31),"",INDEX([1]A1!H$9:H$175,MATCH(1,--(RIGHT([1]A1!$B$9:$B$175,LEN([1]A1!$B$9:$B$175)-4)=$A32)*([1]A1!$C$9:$C$175=YEAR($F32)),0)))} -> 2.5656969e+08 | L32: {=IF(EDATE($F32,L$2)>DATE(2025,12,31),"",INDEX([1]A1!I$9:I$175,MATCH(1,--(RIGHT([1]A1!$B$9:$B$175,LEN([1]A1!$B$9:$B$175)-4)=$A32)*([1]A1!$C$9:$C$175=YEAR($F32)),0)))} -> 2.5863943e+08 | M32: {=IF(EDATE($F32,M$2)>DATE(2025,12,31),"",INDEX([1]A1!J$9:J$175,MATCH(1,--(RIGHT([1]A1!$B$9:$B$175,LEN([1]A1!$B$9:$B$175)-4)=$A32)*([1]A1!$C$9:$C$175=YEAR($F32)),0)))} -> 2.592705e+08 | N32: {=IF(EDATE($F32,N$2)>DATE(2025,12,31),"",INDEX([1]A1!K$9:K$175,MATCH(1,--(RIGHT([1]A1!$B$9:$B$175,LEN([1]A1!$B$9:$B$175)-4)=$A32)*([1]A1!$C$9:$C$175=YEAR($F32)),0)))} -> 2.5938028e+08 | ... FA32: {=IF(EDATE($F32,FA$2)>DATE(2025,12,31),"",INDEX([1]A1!EX$9:EX$175,MATCH(1,--(RIGHT([1]A1!$B$9:$B$175,LEN([1]A1!$B$9:$B$175)-4)=$A32)*([1]A1!$C$9:$C$175=YEAR($F32)),0)))}
A33: Liability | B33: Net Written Premium | C33: All | D33: UW Year | E33: USD | F33: =EDATE(F32,12) -> 42005 | G33: {=IF(EDATE($F33,G$2)>DATE(2025,12,31),"",INDEX([1]A1!D$9:D$175,MATCH(1,--(RIGHT([1]A1!$B$9:$B$175,LEN([1]A1!$B$9:$B$175)-4)=$A33)*([1]A1!$C$9:$C$175=YEAR($F33)),0)))} -> 2.2760227e+08 | H33: {=IF(EDATE($F33,H$2)>DATE(2025,12,31),"",INDEX([1]A1!E$9:E$175,MATCH(1,--(RIGHT([1]A1!$B$9:$B$175,LEN([1]A1!$B$9:$B$175)-4)=$A33)*([1]A1!$C$9:$C$175=YEAR($F33)),0)))} -> 2.8155861e+08 | I33: {=IF(EDATE($F33,I$2)>DATE(2025,12,31),"",INDEX([1]A1!F$9:F$175,MATCH(1,--(RIGHT([1]A1!$B$9:$B$175,LEN([1]A1!$B$9:$B$175)-4)=$A33)*([1]A1!$C$9:$C$175=YEAR($F33)),0)))} -> 2.7919315e+08 | J33: {=IF(EDATE($F33,J$2)>DATE(2025,12,31),"",INDEX([1]A1!G$9:G$175,MATCH(1,--(RIGHT([1]A1!$B$9:$B$175,LEN([1]A1!$B$9:$B$175)-4)=$A33)*([1]A1!$C$9:$C$175=YEAR($F33)),0)))} -> 2.8254937e+08 | K33: {=IF(EDATE($F33,K$2)>DATE(2025,12,31),"",INDEX([1]A1!H$9:H$175,MATCH(1,--(RIGHT([1]A1!$B$9:$B$175,LEN([1]A1!$B$9:$B$175)-4)=$A33)*([1]A1!$C$9:$C$175=YEAR($F33)),0)))} -> 2.8410302e+08 | L33: {=IF(EDATE($F33,L$2)>DATE(2025,12,31),"",INDEX([1]A1!I$9:I$175,MATCH(1,--(RIGHT([1]A1!$B$9:$B$175,LEN([1]A1!$B$9:$B$175)-4)=$A33)*([1]A1!$C$9:$C$175=YEAR($F33)),0)))} -> 2.850038e+08 | M33: {=IF(EDATE($F33,M$2)>DATE(2025,12,31),"",INDEX([1]A1!J$9:J$175,MATCH(1,--(RIGHT([1]A1!$B$9:$B$175,LEN([1]A1!$B$9:$B$175)-4)=$A33)*([1]A1!$C$9:$C$175=YEAR($F33)),0)))} -> 2.8532352e+08 | N33: {=IF(EDATE($F33,N$2)>DATE(2025,12,31),"",INDEX([1]A1!K$9:K$175,MATCH(1,--(RIGHT([1]A1!$B$9:$B$175,LEN([1]A1!$B$9:$B$175)-4)=$A33)*([1]A1!$C$9:$C$175=YEAR($F33)),0)))} -> 2.8569873e+08 | ... FA33: {=IF(EDATE($F33,FA$2)>DATE(2025,12,31),"",INDEX([1]A1!EX$9:EX$175,MATCH(1,--(RIGHT([1]A1!$B$9:$B$175,LEN([1]A1!$B$9:$B$175)-4)=$A33)*([1]A1!$C$9:$C$175=YEAR($F33)),0)))}
A34: Liability | B34: Net Written Premium | C34: All | D34: UW Year | E34: USD | F34: =EDATE(F33,12) -> 42370 | G34: {=IF(EDATE($F34,G$2)>DATE(2025,12,31),"",INDEX([1]A1!D$9:D$175,MATCH(1,--(RIGHT([1]A1!$B$9:$B$175,LEN([1]A1!$B$9:$B$175)-4)=$A34)*([1]A1!$C$9:$C$175=YEAR($F34)),0)))} -> 3.0499874e+08 | H34: {=IF(EDATE($F34,H$2)>DATE(2025,12,31),"",INDEX([1]A1!E$9:E$175,MATCH(1,--(RIGHT([1]A1!$B$9:$B$175,LEN([1]A1!$B$9:$B$175)-4)=$A34)*([1]A1!$C$9:$C$175=YEAR($F34)),0)))} -> 3.4835083e+08 | I34: {=IF(EDATE($F34,I$2)>DATE(2025,12,31),"",INDEX([1]A1!F$9:F$175,MATCH(1,--(RIGHT([1]A1!$B$9:$B$175,LEN([1]A1!$B$9:$B$175)-4)=$A34)*([1]A1!$C$9:$C$175=YEAR($F34)),0)))} -> 3.5238353e+08 | J34: {=IF(EDATE($F34,J$2)>DATE(2025,12,31),"",INDEX([1]A1!G$9:G$175,MATCH(1,--(RIGHT([1]A1!$B$9:$B$175,LEN([1]A1!$B$9:$B$175)-4)=$A34)*([1]A1!$C$9:$C$175=YEAR($F34)),0)))} -> 3.4601942e+08 | K34: {=IF(EDATE($F34,K$2)>DATE(2025,12,31),"",INDEX([1]A1!H$9:H$175,MATCH(1,--(RIGHT([1]A1!$B$9:$B$175,LEN([1]A1!$B$9:$B$175)-4)=$A34)*([1]A1!$C$9:$C$175=YEAR($F34)),0)))} -> 3.4755634e+08 | L34: {=IF(EDATE($F34,L$2)>DATE(2025,12,31),"",INDEX([1]A1!I$9:I$175,MATCH(1,--(RIGHT([1]A1!$B$9:$B$175,LEN([1]A1!$B$9:$B$175)-4)=$A34)*([1]A1!$C$9:$C$175=YEAR($F34)),0)))} -> 3.4891161e+08 | M34: {=IF(EDATE($F34,M$2)>DATE(2025,12,31),"",INDEX([1]A1!J$9:J$175,MATCH(1,--(RIGHT([1]A1!$B$9:$B$175,LEN([1]A1!$B$9:$B$175)-4)=$A34)*([1]A1!$C$9:$C$175=YEAR($F34)),0)))} -> 3.4947306e+08 | N34: {=IF(EDATE($F34,N$2)>DATE(2025,12,31),"",INDEX([1]A1!K$9:K$175,MATCH(1,--(RIGHT([1]A1!$B$9:$B$175,LEN([1]A1!$B$9:$B$175)-4)=$A34)*([1]A1!$C$9:$C$175=YEAR($F34)),0)))} -> 3.4994779e+08 | ... FA34: {=IF(EDATE($F34,FA$2)>DATE(2025,12,31),"",INDEX([1]A1!EX$9:EX$175,MATCH(1,--(RIGHT([1]A1!$B$9:$B$175,LEN([1]A1!$B$9:$B$175)-4)=$A34)*([1]A1!$C$9:$C$175=YEAR($F34)),0)))}
A35: Liability | B35: Net Written Premium | C35: All | D35: UW Year | E35: USD | F35: =EDATE(F34,12) -> 42736 | G35: {=IF(EDATE($F35,G$2)>DATE(2025,12,31),"",INDEX([1]A1!D$9:D$175,MATCH(1,--(RIGHT([1]A1!$B$9:$B$175,LEN([1]A1!$B$9:$B$175)-4)=$A35)*([1]A1!$C$9:$C$175=YEAR($F35)),0)))} -> 3.1247014e+08 | H35: {=IF(EDATE($F35,H$2)>DATE(2025,12,31),"",INDEX([1]A1!E$9:E$175,MATCH(1,--(RIGHT([1]A1!$B$9:$B$175,LEN([1]A1!$B$9:$B$175)-4)=$A35)*([1]A1!$C$9:$C$175=YEAR($F35)),0)))} -> 3.6900858e+08 | I35: {=IF(EDATE($F35,I$2)>DATE(2025,12,31),"",INDEX([1]A1!F$9:F$175,MATCH(1,--(RIGHT([1]A1!$B$9:$B$175,LEN([1]A1!$B$9:$B$175)-4)=$A35)*([1]A1!$C$9:$C$175=YEAR($F35)),0)))} -> 3.7875941e+08 | J35: {=IF(EDATE($F35,J$2)>DATE(2025,12,31),"",INDEX([1]A1!G$9:G$175,MATCH(1,--(RIGHT([1]A1!$B$9:$B$175,LEN([1]A1!$B$9:$B$175)-4)=$A35)*([1]A1!$C$9:$C$175=YEAR($F35)),0)))} -> 3.7895342e+08 | K35: {=IF(EDATE($F35,K$2)>DATE(2025,12,31),"",INDEX([1]A1!H$9:H$175,MATCH(1,--(RIGHT([1]A1!$B$9:$B$175,LEN([1]A1!$B$9:$B$175)-4)=$A35)*([1]A1!$C$9:$C$175=YEAR($F35)),0)))} -> 3.812484e+08 | L35: {=IF(EDATE($F35,L$2)>DATE(2025,12,31),"",INDEX([1]A1!I$9:I$175,MATCH(1,--(RIGHT([1]A1!$B$9:$B$175,LEN([1]A1!$B$9:$B$175)-4)=$A35)*([1]A1!$C$9:$C$175=YEAR($F35)),0)))} -> 3.8327202e+08 | M35: {=IF(EDATE($F35,M$2)>DATE(2025,12,31),"",INDEX([1]A1!J$9:J$175,MATCH(1,--(RIGHT([1]A1!$B$9:$B$175,LEN([1]A1!$B$9:$B$175)-4)=$A35)*([1]A1!$C$9:$C$175=YEAR($F35)),0)))} -> 3.8441817e+08 | N35: {=IF(EDATE($F35,N$2)>DATE(2025,12,31),"",INDEX([1]A1!K$9:K$175,MATCH(1,--(RIGHT([1]A1!$B$9:$B$175,LEN([1]A1!$B$9:$B$175)-4)=$A35)*([1]A1!$C$9:$C$175=YEAR($F35)),0)))} -> 3.8544773e+08 | ... FA35: {=IF(EDATE($F35,FA$2)>DATE(2025,12,31),"",INDEX([1]A1!EX$9:EX$175,MATCH(1,--(RIGHT([1]A1!$B$9:$B$175,LEN([1]A1!$B$9:$B$175)-4)=$A35)*([1]A1!$C$9:$C$175=YEAR($F35)),0)))}
A36: Liability | B36: Net Written Premium | C36: All | D36: UW Year | E36: USD | F36: =EDATE(F35,12) -> 43101 | G36: {=IF(EDATE($F36,G$2)>DATE(2025,12,31),"",INDEX([1]A1!D$9:D$175,MATCH(1,--(RIGHT([1]A1!$B$9:$B$175,LEN([1]A1!$B$9:$B$175)-4)=$A36)*([1]A1!$C$9:$C$175=YEAR($F36)),0)))} -> 3.0617633e+08 | H36: {=IF(EDATE($F36,H$2)>DATE(2025,12,31),"",INDEX([1]A1!E$9:E$175,MATCH(1,--(RIGHT([1]A1!$B$9:$B$175,LEN([1]A1!$B$9:$B$175)-4)=$A36)*([1]A1!$C$9:$C$175=YEAR($F36)),0)))} -> 3.7597247e+08 | I36: {=IF(EDATE($F36,I$2)>DATE(2025,12,31),"",INDEX([1]A1!F$9:F$175,MATCH(1,--(RIGHT([1]A1!$B$9:$B$175,LEN([1]A1!$B$9:$B$175)-4)=$A36)*([1]A1!$C$9:$C$175=YEAR($F36)),0)))} -> 3.9091174e+08 | J36: {=IF(EDATE($F36,J$2)>DATE(2025,12,31),"",INDEX([1]A1!G$9:G$175,MATCH(1,--(RIGHT([1]A1!$B$9:$B$175,LEN([1]A1!$B$9:$B$175)-4)=$A36)*([1]A1!$C$9:$C$175=YEAR($F36)),0)))} -> 3.8335907e+08 | K36: {=IF(EDATE($F36,K$2)>DATE(2025,12,31),"",INDEX([1]A1!H$9:H$175,MATCH(1,--(RIGHT([1]A1!$B$9:$B$175,LEN([1]A1!$B$9:$B$175)-4)=$A36)*([1]A1!$C$9:$C$175=YEAR($F36)),0)))} -> 3.8472683e+08 | L36: {=IF(EDATE($F36,L$2)>DATE(2025,12,31),"",INDEX([1]A1!I$9:I$175,MATCH(1,--(RIGHT([1]A1!$B$9:$B$175,LEN([1]A1!$B$9:$B$175)-4)=$A36)*([1]A1!$C$9:$C$175=YEAR($F36)),0)))} -> 3.8515627e+08 | M36: {=IF(EDATE($F36,M$2)>DATE(2025,12,31),"",INDEX([1]A1!J$9:J$175,MATCH(1,--(RIGHT([1]A1!$B$9:$B$175,LEN([1]A1!$B$9:$B$175)-4)=$A36)*([1]A1!$C$9:$C$175=YEAR($F36)),0)))} -> 3.8646031e+08 | N36: {=IF(EDATE($F36,N$2)>DATE(2025,12,31),"",INDEX([1]A1!K$9:K$175,MATCH(1,--(RIGHT([1]A1!$B$9:$B$175,LEN([1]A1!$B$9:$B$175)-4)=$A36)*([1]A1!$C$9:$C$175=YEAR($F36)),0)))} -> 3.8713735e+08 | ... FA36: {=IF(EDATE($F36,FA$2)>DATE(2025,12,31),"",INDEX([1]A1!EX$9:EX$175,MATCH(1,--(RIGHT([1]A1!$B$9:$B$175,LEN([1]A1!$B$9:$B$175)-4)=$A36)*([1]A1!$C$9:$C$175=YEAR($F36)),0)))}
... A43: Liability | B43: Net Written Premium | C43: All | D43: UW Year | E43: USD | F43: =EDATE(F42,12) -> 45658 | G43: {=IF(EDATE($F43,G$2)>DATE(2025,12,31),"",INDEX([1]A1!D$9:D$175,MATCH(1,--(RIGHT([1]A1!$B$9:$B$175,LEN([1]A1!$B$9:$B$175)-4)=$A43)*([1]A1!$C$9:$C$175=YEAR($F43)),0)))} -> 4.009371e+08 | H43: {=IF(EDATE($F43,H$2)>DATE(2025,12,31),"",INDEX([1]A1!E$9:E$175,MATCH(1,--(RIGHT([1]A1!$B$9:$B$175,LEN([1]A1!$B$9:$B$175)-4)=$A43)*([1]A1!$C$9:$C$175=YEAR($F43)),0)))} | I43: {=IF(EDATE($F43,I$2)>DATE(2025,12,31),"",INDEX([1]A1!F$9:F$175,MATCH(1,--(RIGHT([1]A1!$B$9:$B$175,LEN([1]A1!$B$9:$B$175)-4)=$A43)*([1]A1!$C$9:$C$175=YEAR($F43)),0)))} | J43: {=IF(EDATE($F43,J$2)>DATE(2025,12,31),"",INDEX([1]A1!G$9:G$175,MATCH(1,--(RIGHT([1]A1!$B$9:$B$175,LEN([1]A1!$B$9:$B$175)-4)=$A43)*([1]A1!$C$9:$C$175=YEAR($F43)),0)))} | K43: {=IF(EDATE($F43,K$2)>DATE(2025,12,31),"",INDEX([1]A1!H$9:H$175,MATCH(1,--(RIGHT([1]A1!$B$9:$B$175,LEN([1]A1!$B$9:$B$175)-4)=$A43)*([1]A1!$C$9:$C$175=YEAR($F43)),0)))} | L43: {=IF(EDATE($F43,L$2)>DATE(2025,12,31),"",INDEX([1]A1!I$9:I$175,MATCH(1,--(RIGHT([1]A1!$B$9:$B$175,LEN([1]A1!$B$9:$B$175)-4)=$A43)*([1]A1!$C$9:$C$175=YEAR($F43)),0)))} | M43: {=IF(EDATE($F43,M$2)>DATE(2025,12,31),"",INDEX([1]A1!J$9:J$175,MATCH(1,--(RIGHT([1]A1!$B$9:$B$175,LEN([1]A1!$B$9:$B$175)-4)=$A43)*([1]A1!$C$9:$C$175=YEAR($F43)),0)))} | N43: {=IF(EDATE($F43,N$2)>DATE(2025,12,31),"",INDEX([1]A1!K$9:K$175,MATCH(1,--(RIGHT([1]A1!$B$9:$B$175,LEN([1]A1!$B$9:$B$175)-4)=$A43)*([1]A1!$C$9:$C$175=YEAR($F43)),0)))} | ... FA43: {=IF(EDATE($F43,FA$2)>DATE(2025,12,31),"",INDEX([1]A1!EX$9:EX$175,MATCH(1,--(RIGHT([1]A1!$B$9:$B$175,LEN([1]A1!$B$9:$B$175)-4)=$A43)*([1]A1!$C$9:$C$175=YEAR($F43)),0)))}
A45: Credit & Surety | B45: Net Written Premium | C45: All | D45: UW Year | E45: USD | F45: =triangle_start_date -> 38718 | G45: {=IF(EDATE($F45,G$2)>DATE(2025,12,31),"",INDEX([1]A1!D$9:D$175,MATCH(1,--(RIGHT([1]A1!$B$9:$B$175,LEN([1]A1!$B$9:$B$175)-4)=$A45)*([1]A1!$C$9:$C$175=YEAR($F45)),0)))} -> 33964946 | H45: {=IF(EDATE($F45,H$2)>DATE(2025,12,31),"",INDEX([1]A1!E$9:E$175,MATCH(1,--(RIGHT([1]A1!$B$9:$B$175,LEN([1]A1!$B$9:$B$175)-4)=$A45)*([1]A1!$C$9:$C$175=YEAR($F45)),0)))} -> 85747183 | I45: {=IF(EDATE($F45,I$2)>DATE(2025,12,31),"",INDEX([1]A1!F$9:F$175,MATCH(1,--(RIGHT([1]A1!$B$9:$B$175,LEN([1]A1!$B$9:$B$175)-4)=$A45)*([1]A1!$C$9:$C$175=YEAR($F45)),0)))} -> 93630331 | J45: {=IF(EDATE($F45,J$2)>DATE(2025,12,31),"",INDEX([1]A1!G$9:G$175,MATCH(1,--(RIGHT([1]A1!$B$9:$B$175,LEN([1]A1!$B$9:$B$175)-4)=$A45)*([1]A1!$C$9:$C$175=YEAR($F45)),0)))} -> 95723804 | K45: {=IF(EDATE($F45,K$2)>DATE(2025,12,31),"",INDEX([1]A1!H$9:H$175,MATCH(1,--(RIGHT([1]A1!$B$9:$B$175,LEN([1]A1!$B$9:$B$175)-4)=$A45)*([1]A1!$C$9:$C$175=YEAR($F45)),0)))} -> 97099222 | L45: {=IF(EDATE($F45,L$2)>DATE(2025,12,31),"",INDEX([1]A1!I$9:I$175,MATCH(1,--(RIGHT([1]A1!$B$9:$B$175,LEN([1]A1!$B$9:$B$175)-4)=$A45)*([1]A1!$C$9:$C$175=YEAR($F45)),0)))} -> 97830984 | M45: {=IF(EDATE($F45,M$2)>DATE(2025,12,31),"",INDEX([1]A1!J$9:J$175,MATCH(1,--(RIGHT([1]A1!$B$9:$B$175,LEN([1]A1!$B$9:$B$175)-4)=$A45)*([1]A1!$C$9:$C$175=YEAR($F45)),0)))} -> 98264253 | N45: {=IF(EDATE($F45,N$2)>DATE(2025,12,31),"",INDEX([1]A1!K$9:K$175,MATCH(1,--(RIGHT([1]A1!$B$9:$B$175,LEN([1]A1!$B$9:$B$175)-4)=$A45)*([1]A1!$C$9:$C$175=YEAR($F45)),0)))} -> 98565729 | ... FA45: {=IF(EDATE($F45,FA$2)>DATE(2025,12,31),"",INDEX([1]A1!EX$9:EX$175,MATCH(1,--(RIGHT([1]A1!$B$9:$B$175,LEN([1]A1!$B$9:$B$175)-4)=$A45)*([1]A1!$C$9:$C$175=YEAR($F45)),0)))}
